Workbook

Sheet Fevereiro 
A1: CONTROLE DE HORAS PARADAS - FEVEREIRO
A3: Data | B3: Projeto | C3: Equipe | D3: Equipamento | E3: Horas Totais | F3: Horas Trabalhadas | G3: Horas Paradas | H3: Parada DH_GEL | I3: Parada Parc das artes | J3: Parada Chuva | K3: Parada Mecânica | L3: Outros Motivos | M3: Motivo / Justificativa | N3: Responsável | O3: Nº RDO | P3: Centro de Custo | Q3: Observações
A4: 46062 | B4: 88007 PP25067 - PARC DAS ARTES | C4: 1 TURNO | E4: 0.375 | F4: 0.29166667 | G4: =E4-F4 -> 0.083333333 | H4: 0.083333333 | L4: =SUM(H4:K4) -> 0.083333333 | M4: Aguardando caminhão para nivelar terreno | N4: LEANDRO | Q4: preparando materiais para o projeto
A5: 46063 | B5: 88007 PP25067 - PARC DAS ARTES | C5: 1 TURNO | E5: 0.375 | F5: 0.041666667 | G5: =E5-F5 -> 0.33333333 | H5: 0.33333333 | L5: =SUM(H5:K5) -> 0.33333333 | M5: Agardando caminhão para nivelar terreno/ | N5: LEANDRO | Q5: Tirando medidas da base
A6: 46064 | B6: 88007 PP25067 - PARC DAS ARTES | C6: 1 TURNO | D6: TORNEP | E6: 0.375 | F6: 0.20833333 | G6: =E6-F6 -> 0.16666667 | H6: 0.20833333 | L6: =SUM(H6:K6) -> 0.20833333 | M6: Aguardando equipamento para nivelar terreno/ aguardando concreto. | N6: LEANDRO | O6: 1 | P6: 88007
A7: 46065 | B7: 88007 PP25067 - PARC DAS ARTES | C7: 1 TURNO | D7: TORNEP | E7: 0.375 | F7: 0.097222222 | G7: =E7-F7 -> 0.27777778 | H7: 0.20833333 | L7: =SUM(H7:K7) -> 0.20833333 | M7: Aguardando chegada do concreto | N7: LEANDRO | O7: 2 | P7: 88007
A8: 46066 | B8: 88007 PP25067 - PARC DAS ARTES | C8: 1TURNO | D8: TORNEP | E8: 0.375 | F8: 0.22916667 | G8: =E8-F8 -> 0.14583333 | H8: 0.1875 | L8: =SUM(H8:K8) -> 0.1875 | M8: Conferência da base, manutenção do veiculo de apoio. | N8: LEANDRO | O8: 3 | P8: 88007
A9: 46067 | B9: 88007 PP25067 - PARC DAS ARTES | L9: =SUM(H9:K9) -> 0 | M9: Final de semana | O9: 4 | P9: 88007
A10: 46068 | B10: 88007 PP25067 - PARC DAS ARTES | L10: =SUM(H10:K10) -> 0 | M10: Final de semana | O10: 5 | P10: 88007
A11: 46069 | B11: 88007 PP25067 - PARC DAS ARTES | C11: 1 TURNO | D11: TORNEP | E11: 0.4375 | F11: 0.40277778 | G11: =E11-F11 -> 0.034722222 | H11: 0.034722222 | L11: =SUM(H11:K11) -> 0.034722222 | M11: Deslocamento | N11: LEANDRO | O11: 6 | P11: 88007
A12: 46070 | B12: 88007 PP25067 - PARC DAS ARTES | C12: 1 TURNO | D12: TORNEP | E12: 0.375 | F12: 0.16666667 | G12: =E12-F12 -> 0.20833333 | H12: 0.069444444 | K12: 0.13888889 | L12: =SUM(H12:K12) -> 0.20833333 | M12: Deslocamento / manutenção do equipamento | N12: LEANDRO | O12: 7 | P12: 88007
A13: 46071 | B13: 88007 PP25067 - PARC DAS ARTES | C13: 1 TURNO | D13: TORNEP | E13: 0.375 | F13: 0.375 | G13: =E13-F13 -> 0 | L13: =SUM(H13:K13) -> 0 | N13: LEANDRO | O13: 8 | P13: 88007
A14: 46072 | B14: 88007 PP25067 - PARC DAS ARTES | C14: 1 TURNO | D14: TORNEP | E14: 0.41666667 | F14: 0.25 | G14: =E14-F14 -> 0.16666667 | K14: 0.16666667 | L14: =SUM(H14:K14) -> 0.16666667 | M14: Fazendo instalação eletrica | N14: LEANDRO | O14: 9 | P14: 88007
A15: 46073 | B15: 88007 PP25067 - PARC DAS ARTES | C15: 1 TURNO | D15: TORNEP | E15: 0.39583333 | F15: 0.39583333 | G15: =E15-F15 -> 0 | L15: =SUM(H15:K15) -> 0 | N15: LEANDRO | O15: 10 | P15: 88007
A16: 46074 | B16: 88007 PP25067 - PARC DAS ARTES | C16: 1 TURNO | D16: TORNEP | E16: 0.41666667 | F16: 0.41666667 | G16: =E16-F16 -> 0 | L16: =SUM(H16:K16) -> 0 | N16: LEANDRO | O16: 11 | P16: 88007
A17: 46075 | B17: 88007 PP25067 - PARC DAS ARTES | C17: 1 TURNO | D17: TORNEP | E17: 0.375 | F17: 0.33472222 | G17: =E17-F17 -> 0.040277778 | J17: 0.040277778 | L17: =SUM(H17:K17) -> 0.040277778 | M17: Parada por motivos climaticos (chuva) | N17: LEANDRO | O17: 12 | P17: 88007
A18: 46076 | B18: 88007 PP25067 - PARC DAS ARTES | C18: 1 TURNO | D18: TORNEP | E18: 0.43055556 | F18: 0.43055556 | G18: =E18-F18 -> 0 | L18: =SUM(H18:K18) -> 0 | N18: LEANDRO | O18: 13 | P18: 88007 | Q18: PERFURAÇÃO DE 0 a 6,20M
A19: 46077 | B19: 88007 PP25067 - PARC DAS ARTES | C19: 1 TURNO | D19: TORNEP | E19: 0.43055556 | F19: 0.31597222 | G19: =E19-F19 -> 0.11458333 | K19: 0.11458333 | L19: =SUM(H19:K19) -> 0.11458333 | M19: Manutenção na bomba Gardner Denver | N19: LEANDRO/JOSE PINHEIRO | O19: 14 | P19: 88007 | Q19: PERFURAÇÃO DE 6,20 A 9,20M
A20: 46078 | B20: 88007 PP25067 - PARC DAS ARTES | C20: 1 TURNO | D20: TORNEP | E20: 0.4375 | F20: 0.15972222 | G20: =E20-F20 -> 0.27777778 | K20: 0.27777778 | L20: =SUM(H20:K20) -> 0.27777778 | M20: Manutenção e ajustes das bombas duplex e centrifuga | N20: LEANDRO/JOSE PINHEIRO | O20: 15 | P20: 88007 | Q20: REABERTURA ATÉ 7,29M
A21: 46079 | B21: 88007 PP25067 - PARC DAS ARTES | C21: 1 TURNO | D21: TORNEP | E21: 0.41666667 | F21: 0.41666667 | G21: =E21-F21 -> 0 | L21: =SUM(H21:K21) -> 0 | N21: LEANDRO/JOSE PINHEIRO | O21: 16 | P21: 88007
A22: 46080 | B22: 88007 PP25067 - PARC DAS ARTES | C22: 1 TURNO | D22: TORNEP | E22: 0.33333333 | F22: 0.3125 | G22: =E22-F22 -> 0.020833333 | I22: 0.020833333 | L22: =SUM(H22:K22) -> 0.020833333 | M22: Aguardando o Geólogo da Saerp | N22: CARLOS/JOSE PINHEIRO/LEANDRO | O22: 17 | P22: 88007
A23: 46081 | B23: 88007 PP25067 - PARC DAS ARTES | M23: Não teve atividade - Aguardando cura de cimentação | O23: 18 | P23: 88007
E24: TOTAL | F24: TOTAL | G24: TOTAL | H24: TOTAL | I24: TOTAL | J24: TOTAL | K24: TOTAL
E25: =SUM(E4:E22) -> 6.7152778 | F25: =SUM(F4:F22) -> 4.8451389 | G25: =SUM(G4:G22) -> 1.8701389 | H25: =SUM(H4:H22) -> 1.125 | I25: =SUM(I4:I22) -> 0.020833333 | J25: =SUM(J4:J22) -> 0.040277778 | K25: =SUM(K4:K22) -> 0.69791667
A27: RESUMO AUTOMÁTICO DE HORAS
A29: Total Horas do Projeto | D29: =SUM(E4:E23) -> 6.7152778 | F29: =D29/11 -> 0.6104798 | G29: dias
A30: Total Horas Trabalhadas | D30: =SUM(F4:F23) -> 4.8451389 | F30: =D30/11 -> 0.44046717 | G30: dias
A31: Total Horas Paradas | D31: =SUM(G4:G23) -> 1.8701389 | F31: =D31/11 -> 0.17001263 | G31: dias
A32: Total Horas DH-GEL Engenharia | D32: =SUM(H4:H23) -> 1.125 | F32: =D32/11 -> 0.10227273 | G32: dias
A33: Total Horas Parc das Artes | D33: =SUM(I4:I23) -> 0.020833333 | F33: =D33/11 -> 0.0018939394 | G33: dias
A34: Total Horas Chuva | D34: =SUM(J4:J23) -> 0.040277778 | F34: =D34/11 -> 0.0036616162 | G34: dias
A35: Total Horas Mecânica | D35: =SUM(K4:K23) -> 0.69791667 | F35: =D35/11 -> 0.06344697 | G35: dias
A37: H x H no Projeto | D37: =SUM(F4:F23) -> 4.8451389

Sheet Março
A1: CONTROLE DE HORAS PARADAS - MARÇO
A3: Data | B3: Projeto | C3: Equipe | D3: Equipamento | E3: Horas Totais | F3: Horas Trabalhadas | G3: Horas Paradas | H3: Parada DH_GEL | I3: Parada Parc das artes | J3: Parada Chuva | K3: Parada Mecânica | L3: Outros Motivos | M3: Motivo / Justificativa | N3: Responsável | O3: Nº RDO | P3: Centro de Custo | Q3: Observações
A4: 46082 | B4: 88007 PP25067 - PARC DAS ARTES | D4: TORNEP | L4: =SUM(H4:K4) -> 0 | M4: Sem atividade - aguardando cura da cimentação | O4: 19 | P4: 88007
A5: 46083 | B5: 88007 PP25067 - PARC DAS ARTES | C5: 1 TURNO | D5: TORNEP | E5: 0.41666667 | F5: 0.33333333 | G5: =E5-F5 -> 0.083333333 | H5: 0.083333333 | L5: =SUM(H5:K5) -> 0.083333333 | M5: Reunião de equipe - planejamento / deslocamento | N5: CARLOS/JOSE PINHEIRO/LEANDRO | O5: 20 | P5: 88007 | Q5: Revezamento de equipe- sem paralização para almoço
A6: 46084 | B6: 88007 PP25067 - PARC DAS ARTES | C6: 1 TURNO | D6: TORNEP | E6: 0.5 | F6: 0.48611111 | G6: =E6-F6 -> 0.013888889 | K6: 0.013888889 | L6: =SUM(H6:K6) -> 0.013888889 | M6: ajuste de aperto do swivel | N6: CARLOS/JOSE PINHEIRO/LEANDRO | O6: 21 | P6: 88007 | Q6: Revezamento de equipe- sem paralização para almoço
A7: 46085 | B7: 88007 PP25067 - PARC DAS ARTES | C7: 1 TURNO | D7: TORNEP | E7: 0.5 | F7: 0.28125 | G7: =E7-F7 -> 0.21875 | K7: 0.21875 | L7: =SUM(H7:K7) -> 0.21875 | M7: Troca do parafuso gaxeta/solda no vazamento da conexão kelly, separando kelly p/manutenção. | N7: CARLOS/JOSE PINHEIRO/LEANDRO | O7: 22 | P7: 88007 | Q7: Revezamento de equipe- sem paralização para almoço
A8: 46086 | B8: 88007 PP25067 - PARC DAS ARTES | C8: 1 TURNO | D8: TORNEP | E8: 0.41666667 | F8: 0.32638889 | G8: =E8-F8 -> 0.090277778 | K8: 0.090277778 | L8: =SUM(H8:K8) -> 0.090277778 | M8: Troca do parafuso gaxeta/reforço da solda do kelly | N8: CARLOS/JOSE PINHEIRO/LEANDRO | O8: 23 | P8: 88007 | Q8: Martelo apresentou problema, foi para manutenção
A9: 46087 | B9: 88007 PP25067 - PARC DAS ARTES | C9: 1 TURNO | D9: TORNEP | E9: 0.4375 | F9: 0 | G9: =E9-F9 -> 0.4375 | H9: 0.35416667 | K9: 0.083333333 | L9: =SUM(H9:K9) -> 0.4375 | M9: DTS/ administrativo/ manutenção das mangueiras | N9: CARLOS/JOSE PINHEIRO/LEANDRO | O9: 24 | P9: 88007
A10: 46088 | B10: 88007 PP25067 - PARC DAS ARTES | C10: 1 TURNO | D10: TORNEP | E10: 0.5 | F10: 0.5 | G10: =E10-F10 -> 0 | L10: =SUM(H10:K10) -> 0 | O10: 25 | P10: 88007
A11: 46089 | B11: 88007 PP25067 - PARC DAS ARTES | C11: 1 TURNO | D11: TORNEP | E11: 0.5 | F11: 0.5 | G11: =E11-F11 -> 0 | L11: =SUM(H11:K11) -> 0 | N11: JOSE PINHEIRO | O11: 26 | P11: 88007 | Q11: Perfurou até 52,0 M
A12: 46090 | B12: 88007 PP25067 - PARC DAS ARTES | C12: 1 TURNO | D12: TORNEP | E12: 0.45833333 | F12: 0.42361111 | G12: =E12-F12 -> 0.034722222 | H12: 0.034722222 | L12: =SUM(H12:K12) -> 0.034722222 | M12: Aguardando liberação de perfuração | O12: 27 | P12: 88007 | Q12: perfurou até 63,0 M
A13: 46091 | B13: 88007 PP25067 - PARC DAS ARTES | C13: 1 TURNO | D13: TORNEP | E13: 0.41666667 | F13: 0.41666667 | G13: =E13-F13 -> 0 | L13: =SUM(H13:K13) -> 0 | O13: 28 | P13: 88007 | Q13: Perfurou até 68,0 M - Atingiu Arenito
A14: 46092 | B14: 88007 PP25067 - PARC DAS ARTES | C14: 2 TURNO | D14: TORNEP | E14: 1 | G14: =E14-F14 -> 1 | I14: 1 | L14: =SUM(H14:K14) -> 1 | M14: Aguardando Material - tubos | O14: 29 | P14: 88007
A15: 46093 | B15: 88007 PP25067 - PARC DAS ARTES | C15: 2 TURNO | D15: TORNEP | E15: 1 | G15: =E15-F15 -> 1 | I15: 1 | L15: =SUM(H15:K15) -> 1 | M15: Aguardando Material - tubos | O15: 30 | P15: 88007
A16: 46094 | B16: 88007 PP25067 - PARC DAS ARTES | C16: 2 TURNO | D16: TORNEP | E16: 1 | G16: =E16-F16 -> 1 | I16: 1 | L16: =SUM(H16:K16) -> 1 | M16: Aguardando Material - tubos | O16: 31 | P16: 88007
A17: 46095 | B17: 88007 PP25067 - PARC DAS ARTES | C17: 2 TURNO | D17: TORNEP | E17: 1 | G17: =E17-F17 -> 1 | I17: 1 | L17: =SUM(H17:K17) -> 1 | M17: Aguardando Material - tubos | O17: 32 | P17: 88007
A18: 46096 | B18: 88007 PP25067 - PARC DAS ARTES | C18: 2 TURNO | D18: TORNEP | E18: 1 | G18: =E18-F18 -> 1 | I18: 1 | L18: =SUM(H18:K18) -> 1 | M18: Aguardando Material - tubos | O18: 33 | P18: 88007
A19: 46097 | B19: 88007 PP25067 - PARC DAS ARTES | C19: 2 TURNO | D19: TORNEP | E19: 1 | G19: =E19-F19 -> 1 | I19: 1 | L19: =SUM(H19:K19) -> 1 | M19: Aguardando Material - tubos | O19: 34 | P19: 88007
A20: 46098 | B20: 88007 PP25067 - PARC DAS ARTES | C20: 2 TURNO | D20: TORNEP | E20: 1 | G20: =E20-F20 -> 1 | I20: 1 | L20: =SUM(H20:K20) -> 1 | M20: Aguardando Material - tubos | O20: 35 | P20: 88007
A21: 46099 | B21: 88007 PP25067 - PARC DAS ARTES | C21: 2 TURNO | D21: TORNEP | E21: 1 | G21: =E21-F21 -> 1 | I21: 1 | L21: =SUM(H21:K21) -> 1 | M21: Aguardando Material - tubos | O21: 36 | P21: 88007
A22: 46100 | B22: 88007 PP25067 - PARC DAS ARTES | C22: 1 TURNO | D22: TORNEP | E22: 0.45833333 | F22: 0.33333333 | G22: =E22-F22 -> 0.125 | H22: 0.125 | L22: =SUM(H22:K22) -> 0.125 | M22: Reunião com Equipe - e Aguardando revestimento | O22: 37 | P22: 88007
A23: 46101 | B23: 88007 PP25067 - PARC DAS ARTES | C23: 1 TURNO | D23: TORNEP | E23: 0.41666667 | G23: =E23-F23 -> 0.41666667 | K23: 0.41666667 | L23: =SUM(H23:K23) -> 0.41666667 | M23: verificação do fluido, mau funcionamento na sonda/ deslocamento para buscar compressor | O23: 38 | P23: 88007
A24: 46102 | B24: 88007 PP25067 - PARC DAS ARTES | C24: 1 TURNO | D24: TORNEP | E24: 0.45833333 | F24: 0.45833333 | G24: =E24-F24 -> 0 | L24: =SUM(H24:K24) -> 0 | O24: 39 | P24: 88007 | Q24: Perfurou até 92,0 M
A25: 46103 | B25: 88007 PP25067 - PARC DAS ARTES | C25: 1 TURNO | D25: TORNEP | E25: 0.45833333 | F25: 0.45833333 | G25: =E25-F25 -> 0 | L25: =SUM(H25:K25) -> 0 | O25: 40 | P25: 88007 | Q25: Perfurou até 94,0 M
A26: 46104 | B26: 88007 PP25067 - PARC DAS ARTES | C26: 1 TURNO | D26: TORNEP | E26: 0.50347222 | F26: 0.50347222 | G26: =E26-F26 -> 0 | L26: =SUM(H26:K26) -> 0 | O26: 41 | P26: 88007 | Q26: Perfurou até 126,0 M - Revezamento-s/ paralização p/ almoço
A27: 46105 | B27: 88007 PP25067 - PARC DAS ARTES | C27: 2 TURNO | D27: TORNEP | E27: 1.0208333 | F27: 0.70833333 | G27: =E27-F27 -> 0.3125 | K27: 0.3125 | L27: =SUM(H27:K27) -> 0.3125 | M27: Transporte do pino da catarina para a tornearia | O27: 42 | P27: 88007 | Q27: Perfurou até 142,88 M - Revezamento de equipe- sem paralização para almoço
A28: 46106 | B28: 88007 PP25067 - PARC DAS ARTES | C28: 2 TURNO | D28: TORNEP | E28: 1 | F28: 1 | G28: =E28-F28 -> 0 | L28: =SUM(H28:K28) -> 0 | O28: 43 | P28: 88007 | Q28: Perfurou até 206,0 M
A29: 46107 | B29: 88007 PP25067 - PARC DAS ARTES | C29: 2 TURNO | D29: TORNEP | E29: 0.95833333 | F29: 0.95833333 | G29: =E29-F29 -> 0 | L29: =SUM(H29:K29) -> 0 | O29: 44 | P29: 88007
A30: 46108 | B30: 88007 PP25067 - PARC DAS ARTES | C30: 2 TURNO | D30: TORNEP | E30: 1 | F30: 1 | G30: =E30-F30 -> 0 | L30: =SUM(H30:K30) -> 0 | O30: 45 | P30: 88007 | Q30: Perfurou até 288,90 M
A31: 46109 | B31: 88007 PP25067 - PARC DAS ARTES | C31: 2 TURNO | D31: TORNEP | E31: 0.95833333 | F31: 0.75 | G31: =E31-F31 -> 0.20833333 | K31: 0.20833333 | L31: =SUM(H31:K31) -> 0.20833333 | M31: Deslocamento para buscar fole de embreagem | O31: 46 | P31: 88007
A32: 46110 | B32: 88007 PP25067 - PARC DAS ARTES | C32: 2 TURNO | D32: TORNEP | E32: 0.91666667 | F32: 0.34027778 | G32: =E32-F32 -> 0.57638889 | H32: 0.47916667 | K32: 0.097222222 | L32: =SUM(H32:K32) -> 0.57638889 | M32: Aguardando broca/defeito no fole/arrumando as mangueiras. | O32: 47 | P32: 88007
A33: 46111 | B33: 88007 PP25067 - PARC DAS ARTES | C33: 2 TURNO | D33: TORNEP | E33: 1 | F33: 0.70833333 | G33: =E33-F33 -> 0.29166667 | H33: 0.1875 | K33: 0.10416667 | L33: =SUM(H33:K33) -> 0.29166667 | M33: Arrumando ar do fole/ aguardando Torrista | O33: 48 | P33: 88007 | Q33: Perfurou até 289,20 M
A34: 46112 | B34: 88007 PP25067 - PARC DAS ARTES | C34: 2 TURNO | D34: TORNEP | E34: 1 | F34: 0.69097222 | G34: =E34-F34 -> 0.30902778 | J34: 0.079861111 | K34: 0.22916667 | L34: =SUM(H34:K34) -> 0.30902778 | M34: Reparo no fole da engrenagem - paralização por motivos climaticos. | O34: 49 | P34: 88007
E36: TOTAL | F36: TOTAL | G36: TOTAL | H36: TOTAL | I36: TOTAL | J36: TOTAL | K36: TOTAL
E37: =SUM(E4:E34) -> 22.295139 | F37: =SUM(F4:F34) -> 11.177083 | G37: =SUM(G4:G34) -> 11.118056 | H37: =SUM(H4:H34) -> 1.2638889 | I37: =SUM(I4:I34) -> 8 | J37: =SUM(J4:J34) -> 0.079861111 | K37: =SUM(K4:K34) -> 1.7743056
A39: RESUMO AUTOMÁTICO DE HORAS
A41: Total Horas do Projeto | D41: =SUM(E4:E35) -> 22.295139 | F41: =D41/22 -> 1.0134154 | G41: dias
A42: Total Horas Trabalhadas | D42: =SUM(F4:F35) -> 11.177083 | F42: =D42/22 -> 0.50804924 | G42: dias
A43: Total Horas Paradas | D43: =SUM(G4:G35) -> 11.118056 | F43: =D43/22 -> 0.50536616 | G43: dias
A44: Total Horas DH-GEL Engenharia | D44: =SUM(H4:H35) -> 1.2638889 | F44: =D44/22 -> 0.057449495 | G44: dias
...

Sheet Abril
A1: CONTROLE DE HORAS PARADAS - ABRIL
A3: Data | B3: Projeto | C3: Equipe | D3: Equipamento | E3: Horas Totais | F3: Horas Trabalhadas | G3: Horas Paradas | H3: Parada DH-GEL | I3: Parada Parc das artes | J3: Parada Chuva | K3: Parada Mecânica | L3: Outros Motivos | M3: Motivo / Justificativa | N3: Responsável | O3: Nº RDO | P3: Centro de Custo | Q3: Observações
A4: 46113 | B4: 88007 PP25067 - PARC DAS ARTES | C4: 2 TURNO | D4: TORNEP | E4: 0.95833333 | F4: 0.41666667 | G4: =E4-F4 -> 0.54166667 | H4: 0.45833333 | J4: 0.083333333 | L4: =SUM(H4:K4) -> 0.54166667 | M4: Paralização devido a motivos climaticos (chuva forte)/falta de equipe | O4: 50 | P4: 88007 | Q4: Perfurou até 310M
A5: 46114 | B5: 88007 PP25067 - PARC DAS ARTES | C5: 2 TURNO | D5: TORNEP | E5: 0.93055556 | F5: 0.33333333 | G5: =E5-F5 -> 0.59722222 | H5: 0.59722222 | L5: =SUM(H5:K5) -> 0.59722222 | M5: Deslocamento/falta de equipe | O5: 51 | P5: 88007
A6: 46115 | B6: 88007 PP25067 - PARC DAS ARTES | C6: 1 TURNO | D6: TORNEP | E6: 0.45833333 | G6: =E6-F6 -> 0.45833333 | H6: 0.45833333 | L6: =SUM(H6:K6) -> 0.45833333 | M6: Sem atividade - falta de equipe | O6: 52 | P6: 88007
A7: 46116 | B7: 88007 PP25067 - PARC DAS ARTES | C7: 1 TURNO | D7: TORNEP | E7: 0.45833333 | G7: =E7-F7 -> 0.45833333 | H7: 0.45833333 | L7: =SUM(H7:K7) -> 0.45833333 | M7: Sem atividade - falta de equipe | O7: 53 | P7: 88007
A8: 46117 | B8: 88007 PP25067 - PARC DAS ARTES | C8: 1 TURNO | D8: TORNEP | E8: 0.45833333 | G8: =E8-F8 -> 0.45833333 | H8: 0.45833333 | L8: =SUM(H8:K8) -> 0.45833333 | M8: Sem atividade - falta de equipe | O8: 54 | P8: 88007
A9: 46118 | B9: 88007 PP25067 - PARC DAS ARTES | C9: 1 TURNO | D9: TORNEP | E9: 0.45833333 | F9: 0.16666667 | G9: =E9-F9 -> 0.29166667 | H9: 0.29166667 | L9: =SUM(H9:K9) -> 0.29166667 | M9: Executada a desmontagem da bomba e linha de lama, seguida do carregamento para transporte à obra da MRV, 'Realizando a organização do canteiro, permanecendo em espera. | O9: 55 | P9: 88007
A10: 46119 | B10: 88007 PP25067 - PARC DAS ARTES | C10: 2 TURNO | D10: TORNEP | E10: 1.0416667 | F10: 0.78472222 | G10: =E10-F10 -> 0.25694444 | H10: 0.19444444 | J10: 0.0625 | L10: =SUM(H10:K10) -> 0.25694444 | M10: Deslocamento de R.Bonito P/ R.Preto/ Aguardando bomba de pistão/aguardando munck1/Motivos climaticos (chuva) | O10: 56 | P10: 88007
A11: 46120 | B11: 88007 PP25067 - PARC DAS ARTES | C11: 2 TURNO | D11: TORNEP | E11: 0.91666667 | F11: 0.80277778 | G11: =E11-F11 -> 0.11388889 | K11: 0.11388889 | L11: =SUM(H11:K11) -> 0.11388889 | M11: Reparo tubo do fole da embreagem | O11: 57 | P11: 88007 | Q11: revezamento de equipe:no almoço/janta- Perfurou até 290,90 M.
A12: 46121 | B12: 88007 PP25067 - PARC DAS ARTES | C12: 2 TURNO | D12: TORNEP | E12: 1.0208333 | F12: 1.0208333 | G12: =E12-F12 -> 0 | L12: =SUM(H12:K12) -> 0 | O12: 58 | P12: 88007 | Q12: revezamento de equipe:no almoço/janta- Perfurou até 325,54 M
A13: 46122 | B13: 88007 PP25067 - PARC DAS ARTES | C13: 2 TURNO | D13: TORNEP | E13: 0.91666667 | F13: 0.70833333 | G13: =E13-F13 -> 0.20833333 | K13: 0.20833333 | L13: =SUM(H13:K13) -> 0.20833333 | M13: Troca da graxeta da bomba centrifuga/Revisão da bomba | O13: 59 | P13: 88007 | Q13: Perfurou até 332,43 M
A14: 46123 | B14: 88007 PP25067 - PARC DAS ARTES | C14: 2 TURNO | D14: TORNEP | E14: 1 | F14: 0.5 | G14: =E14-F14 -> 0.5 | H14: 0.5 | L14: =SUM(H14:K14) -> 0.5 | M14: Falta de equipe | O14: 60 | P14: 88007 | Q14: Perfurou até 352,89 M
A15: 46124 | B15: 88007 PP25067 - PARC DAS ARTES | C15: 2 TURNO | D15: TORNEP | E15: 1 | F15: 0.33333333 | G15: =E15-F15 -> 0.66666667 | H15: 0.5 | K15: 0.16666667 | L15: =SUM(H15:K15) -> 0.66666667 | M15: Reparo por solda no underreamer/falta de equipe | O15: 61 | P15: 88007
A16: 46125 | B16: 88007 PP25067 - PARC DAS ARTES | C16: 2 TURNO | D16: TORNEP | E16: 0.96527778 | F16: 0.63194444 | G16: =E16-F16 -> 0.33333333 | K16: 0.33333333 | L16: =SUM(H16:K16) -> 0.33333333 | M16: Arrumando fole da embreagem de mesa/Arrumando fole da sonda. | O16: 62 | P16: 88007
A17: 46126 | B17: 88007 PP25067 - PARC DAS ARTES | C17: 2 TURNO | D17: TORNEP | E17: 1 | F17: 0.73958333 | G17: =E17-F17 -> 0.26041667 | K17: 0.26041667 | L17: =SUM(H17:K17) -> 0.26041667 | M17: Arrumando junta da bomba / apertando o suiwel / arrumando mangueira e conexão de ar do fole de mesa | O17: 63 | P17: 88007 | Q17: Reabriu até 218 M
A18: 46127 | B18: 88007 PP25067 - PARC DAS ARTES | C18: 2 TURNO | D18: TORNEP | E18: 0.91666667 | F18: 0.29166667 | G18: =E18-F18 -> 0.625 | H18: 0.45833333 | K18: 0.16666667 | L18: =SUM(H18:K18) -> 0.625 | M18: Aguardando peças do underreamer (pinos do braço)/falta de equipe | O18: 64 | P18: 88007
A19: 46128 | B19: 88007 PP25067 - PARC DAS ARTES | C19: 2 TURNO | D19: TORNEP | E19: 0.95833333 | F19: 0.79166667 | G19: =E19-F19 -> 0.16666667 | K19: 0.16666667 | L19: =SUM(H19:K19) -> 0.16666667 | M19: Manutenção do underreamer | O19: 65 | P19: 88007
A20: 46129 | B20: 88007 PP25067 - PARC DAS ARTES | C20: 2 TURNO | D20: TORNEP | E20: 1 | F20: 1 | G20: =E20-F20 -> 0 | L20: =SUM(H20:K20) -> 0 | M20: Limpeza do fundo do poço 355 M/Material decantado | O20: 66 | P20: 88007 | Q20: Revezamento de equipe: no almoço/janta
A21: 46130 | B21: 88007 PP25067 - PARC DAS ARTES | C21: 2 TURNO | D21: TORNEP | E21: 0.95833333 | F21: 0.875 | G21: =E21-F21 -> 0.083333333 | K21: 0.083333333 | L21: =SUM(H21:K21) -> 0.083333333 | M21: Manutenção do underreamer/manutenção da bomba emsco | O21: 67 | P21: 88007
A22: 46131 | B22: 88007 PP25067 - PARC DAS ARTES | C22: 2 TURNO | D22: TORNEP | E22: 1 | F22: 1 | G22: =E22-F22 -> 0 | L22: =SUM(H22:K22) -> 0 | M22: Instalação eletrica | O22: 68 | P22: 88007 | Q22: Reabriu com underreamer até 345 M
A23: 46132 | B23: 88007 PP25067 - PARC DAS ARTES | C23: 2 TURNO | D23: TORNEP | E23: 0.91666667 | F23: 0.78472222 | G23: =E23-F23 -> 0.13194444 | H23: 0.13194444 | L23: =SUM(H23:K23) -> 0.13194444 | M23: testando e verificando catarina/ DTM carregamento de munck | O23: 69 | P23: 88007
A24: 46133 | B24: 88007 PP25067 - PARC DAS ARTES | C24: 2 TURNO | D24: TORNEP | E24: 0.95833333 | F24: 0.86458333 | G24: =E24-F24 -> 0.09375 | H24: 0.09375 | L24: =SUM(H24:K24) -> 0.09375 | M24: descarregando ferramenta | O24: 70 | P24: 88007
A25: 46134 | B25: 88007 PP25067 - PARC DAS ARTES | C25: 2 TURNO | D25: TORNEP | E25: 0.9375 | F25: 0.9375 | G25: =E25-F25 -> 0 | L25: =SUM(H25:K25) -> 0 | O25: 71 | P25: 88007
A26: 46135 | B26: 88007 PP25067 - PARC DAS ARTES | C26: 2 TURNO | D26: TORNEP | E26: 0.93402778 | F26: 0.59375 | G26: =E26-F26 -> 0.34027778 | H26: 0.34027778 | L26: =SUM(H26:K26) -> 0.34027778 | M26: Aguardando Oxigenio acetileno/ aguardando material | O26: 72 | P26: 88007
A27: 46136 | B27: 88007 PP25067 - PARC DAS ARTES | C27: 2 TURNO | D27: TORNEP | E27: 0.97222222 | F27: 0.92361111 | G27: =E27-F27 -> 0.048611111 | K27: 0.048611111 | L27: =SUM(H27:K27) -> 0.048611111 | M27: Manutenção sistema de scção bomba emsco | O27: 73 | P27: 88007
A28: 46137 | B28: 88007 PP25067 - PARC DAS ARTES | C28: 2 TURNO | D28: TORNEP | E28: 1 | F28: 1 | G28: =E28-F28 -> 0 | L28: =SUM(H28:K28) -> 0 | O28: 74 | P28: 88007 | Q28: Revezamento de equipe: no almoço/janta
A29: 46138 | B29: 88007 PP25067 - PARC DAS ARTES | C29: 2 TURNO | D29: TORNEP | E29: 1 | F29: 1 | G29: =E29-F29 -> 0 | L29: =SUM(H29:K29) -> 0 | O29: 75 | P29: 88007 | Q29: Revezamento de equipe: no almoço/janta
A30: 46139 | B30: 88007 PP25067 - PARC DAS ARTES | C30: 1 TURNO | D30: TORNEP | E30: 0.5 | F30: 0.5 | G30: =E30-F30 -> 0 | L30: =SUM(H30:K30) -> 0 | O30: 76 | P30: 88007
A31: 46140 | B31: 88007 PP25067 - PARC DAS ARTES | C31: 1 TURNO | D31: TORNEP | E31: 0.45833333 | F31: 0.35416667 | G31: =E31-F31 -> 0.10416667 | H31: 0.10416667 | L31: =SUM(H31:K31) -> 0.10416667 | M31: Descarregando caminhão | O31: 77 | P31: 88007
A32: 46141 | B32: 88007 PP25067 - PARC DAS ARTES | C32: 2 TURNO | D32: TORNEP | E32: 0.97916667 | F32: 0.72916667 | G32: =E32-F32 -> 0.25 | H32: 0.0625 | I32: 0.1875 | L32: =SUM(H32:K32) -> 0.25 | M32: Admistrativo DH / Aguardando definição do parc das artes para desenvolvimento do poço | O32: 78 | P32: 88007
A33: 46142 | B33: 88007 PP25067 - PARC DAS ARTES | C33: 1 TURNO | D33: TORNEP | E33: 0.5 | F33: 0.5 | G33: =E33-F33 -> 0 | L33: =SUM(H33:K33) -> 0 | M33: DTM Parc das artes/Artesano | O33: 79 | P33: 88007
E34: TOTAL | F34: TOTAL | G34: TOTAL | H34: TOTAL | I34: TOTAL | J34: TOTAL | K34: TOTAL
E35: =SUM(E4:E33) -> 25.572917 | F35: =SUM(F4:F33) -> 18.584028 | G35: =SUM(G4:G33) -> 6.9888889 | H35: =SUM(H4:H33) -> 5.1076389 | I35: =SUM(I4:I33) -> 0.1875 | J35: =SUM(J4:J33) -> 0.14583333 | K35: =SUM(K4:K33) -> 1.5479167
A37: RESUMO AUTOMÁTICO DE HORAS
A39: Total Horas do Projeto | D39: =SUM(E4:E33) -> 25.572917 | F39: =D39/22 -> 1.1624053 | G39: dias
A40: Total Horas Trabalhadas | D40: =SUM(F4:F33) -> 18.584028 | F40: =D40/22 -> 0.84472854 | G40: dias
A41: Total Horas Paradas | D41: =SUM(G4:G33) -> 6.9888889 | F41: =D41/22 -> 0.31767677 | G41: dias
A42: Total Horas DH-GEL Engenharia | D42: =SUM(H4:H33) -> 5.1076389 | F42: =D42/22 -> 0.2321654 | G42: dias
A43: Total Parc das Artes | D43: =SUM(I4:I33) -> 0.1875 | F43: =D43/22 -> 0.0085227273 | G43: dias
...

Sheet Maio 
A1: CONTROLE DE HORAS PARADAS - MAIO
A3: Data | B3: Projeto | C3: Equipe | D3: Equipamento | E3: Horas Totais | F3: Horas Trabalhadas | G3: Horas Paradas | H3: Parada DH_GEL | I3: Parada Parc das artes | J3: Parada Chuva | K3: Parada Mecânica | L3: Outros Motivos | M3: Motivo / Justificativa | N3: Responsável | O3: Nº RDO | P3: Centro de Custo | Q3: Observações
A4: 46143 | B4: 88007 PP25067 - PARC DAS ARTES | C4: 1 TURNO | D4: TORNEP | E4: 0.45833333 | F4: 0.35416667 | G4: =E4-F4 -> 0.10416667 | H4: 0.10416667 | L4: =SUM(H4:K4) -> 0.10416667 | M4: Aguardando jateador | O4: 80 | P4: 88007
A5: 46144 | B5: 88007 PP25067 - PARC DAS ARTES | C5: 1 TURNO | D5: TORNEP | E5: 0.5 | F5: 0.5 | G5: =E5-F5 -> 0 | L5: =SUM(H5:K5) -> 0 | O5: 81 | P5: 88007
A6: 46145 | B6: 88007 PP25067 - PARC DAS ARTES | C6: 1 TURNO | D6: TORNEP | E6: 0.39236111 | F6: 0.39236111 | G6: =E6-F6 -> 0 | L6: =SUM(H6:K6) -> 0 | O6: 82 | P6: 88007
A7: 46146 | B7: 88007 PP25067 - PARC DAS ARTES | C7: 1 TURNO | D7: TORNEP | E7: 0.45833333 | G7: =E7-F7 -> 0.45833333 | I7: 0.45833333 | L7: =SUM(H7:K7) -> 0.45833333 | M7: Aguardando decisão da saerp | O7: 83 | P7: 88007
A8: 46147 | B8: 88007 PP25067 - PARC DAS ARTES | C8: 1 TURNO | D8: TORNEP | E8: 0.45833333 | F8: 0.20486111 | G8: =E8-F8 -> 0.25347222 | I8: 0.25347222 | L8: =SUM(H8:K8) -> 0.25347222 | M8: Aguardando decisão da saerp, se vai ou não assobrar mais o poço. | O8: 84 | P8: 88007
A9: 46148 | B9: 88007 PP25067 - PARC DAS ARTES | C9: 1 TURNO | D9: TORNEP | E9: 0.45833333 | F9: 0.125 | G9: =E9-F9 -> 0.33333333 | I9: 0.33333333 | L9: =SUM(H9:K9) -> 0.33333333 | M9: Aguardando decisão da saerp | O9: 85 | P9: 88007
A10: 46149 | B10: 88007 PP25067 - PARC DAS ARTES | C10: 1 TURNO | D10: TORNEP | E10: 0.45833333 | F10: 0.1875 | G10: =E10-F10 -> 0.27083333 | I10: 0.27083333 | L10: =SUM(H10:K10) -> 0.27083333 | M10: Aguardando decisão da saerp | O10: 86 | P10: 88007
A11: 46150 | B11: 88007 PP25067 - PARC DAS ARTES | C11: 1 TURNO | D11: TORNEP | E11: 0.45833333 | F11: 0.45833333 | G11: =E11-F11 -> 0 | L11: =SUM(H11:K11) -> 0 | O11: 87 | P11: 88007
A12: 46151 | B12: 88007 PP25067 - PARC DAS ARTES | C12: 1 TURNO | D12: TORNEP | E12: 0.45833333 | F12: 0.45833333 | G12: =E12-F12 -> 0 | L12: =SUM(H12:K12) -> 0 | M12: DTM/Artesano / DH | O12: 89 | P12: 88007
A13: 46152 | B13: 88007 PP25067 - PARC DAS ARTES | C13: 1 TURNO | D13: TORNEP | E13: 0.41666667 | F13: 0.41666667 | G13: =E13-F13 -> 0 | L13: =SUM(H13:K13) -> 0 | M13: DTM/Artesano - organizando pátio | O13: 90 | P13: 88007
A14: 46153 | B14: 88007 PP25067 - PARC DAS ARTES | C14: 1 TURNO | D14: TORNEP | E14: 0.43402778 | F14: 0.16666667 | G14: =E14-F14 -> 0.26736111 | H14: 0.26736111 | L14: =SUM(H14:K14) -> 0.26736111 | M14: Aguardando retirada da bomba e sonda | O14: 91 | P14: 88007
A15: 46154 | B15: 88007 PP25067 - PARC DAS ARTES | C15: 1 TURNO | D15: TORNEP | E15: 0.45833333 | F15: 0.45833333 | G15: =E15-F15 -> 0 | L15: =SUM(H15:K15) -> 0 | M15: DTM/Artesano /MRV | O15: 92 | P15: 88007
A16: 46155 | B16: 88007 PP25067 - PARC DAS ARTES | C16: 1 TURNO | D16: TORNEP | E16: 0.45833333 | F16: 0.083333333 | G16: =E16-F16 -> 0.375 | H16: 0.20833333 | I16: 0.16666667 | L16: =SUM(H16:K16) -> 0.375 | M16: 4hs aguardando retro da saerp/5hs aguardando bomba | O16: 93 | P16: 88007
A17: 46156 | B17: 88007 PP25067 - PARC DAS ARTES | C17: 1 TURNO | D17: TORNEP | E17: 0.45833333 | F17: 0.35625 | G17: =E17-F17 -> 0.10208333 | H17: 0.10208333 | L17: =SUM(H17:K17) -> 0.10208333 | M17: Aguardando eletricista/DTM-Artesano | O17: 94 | P17: 88007
A18: 46157 | B18: 88007 PP25067 - PARC DAS ARTES | C18: 1 TURNO | D18: TORNEP | E18: 0.45833333 | F18: 0.39583333 | G18: =E18-F18 -> 0.0625 | J18: 0.0625 | L18: =SUM(H18:K18) -> 0.0625 | M18: DTM/ Paralização por chuva | O18: 95 | P18: 88007
A19: 46158 | B19: 88007 PP25067 - PARC DAS ARTES | C19: 1 TURNO | D19: TORNEP | E19: 0.45833333 | F19: 0.45833333 | G19: =E19-F19 -> 0 | L19: =SUM(H19:K19) -> 0 | O19: 96 | P19: 88007
A20: 46159 | B20: 88007 PP25067 - PARC DAS ARTES | C20: 1 TURNO | D20: TORNEP | E20: 0.45833333 | F20: 0.45833333 | G20: =E20-F20 -> 0 | L20: =SUM(H20:K20) -> 0 | O20: 97 | P20: 88007
A21: 46160 | B21: 88007 PP25067 - PARC DAS ARTES | C21: 1 TURNO | D21: TORNEP | E21: 0.45833333 | F21: 0.45833333 | G21: =E21-F21 -> 0 | L21: =SUM(H21:K21) -> 0 | O21: 98 | P21: 88007
A22: 46161 | B22: 88007 PP25067 - PARC DAS ARTES | C22: 1 TURNO | D22: TORNEP | E22: 0.5 | F22: 0.5 | G22: =E22-F22 -> 0 | L22: =SUM(H22:K22) -> 0 | M22: Bombeamento | O22: 99 | P22: 88007
A23: 46162 | B23: 88007 PP25067 - PARC DAS ARTES | C23: 2 TURNO | D23: TORNEP | E23: 1 | F23: 1 | G23: =E23-F23 -> 0 | L23: =SUM(H23:K23) -> 0 | M23: Bombeamento | O23: 100 | P23: 88007
A24: 46163 | B24: 88007 PP25067 - PARC DAS ARTES | C24: 1 TURNO | D24: TORNEP | E24: 0.45833333 | F24: 0.45833333 | G24: =E24-F24 -> 0 | L24: =SUM(H24:K24) -> 0 | M24: Bombeamento | O24: 101 | P24: 88007
A25: 46164 | B25: 88007 PP25067 - PARC DAS ARTES | C25: 1 TURNO | D25: TORNEP | E25: 0.45833333 | F25: 0.45833333 | G25: =E25-F25 -> 0 | L25: =SUM(H25:K25) -> 0 | M25: Bombeamento | O25: 102 | P25: 88007
A26: 46165 | B26: 88007 PP25067 - PARC DAS ARTES | C26: 2 TURNO | D26: TORNEP | E26: 1 | F26: 0.9375 | G26: =E26-F26 -> 0.0625 | I26: 0.0625 | L26: =SUM(H26:K26) -> 0.0625 | M26: Aguardando ficais para o teste de vazão | O26: 103 | P26: 88007 | Q26: teste de vazão
A27: 46166 | B27: 88007 PP25067 - PARC DAS ARTES | C27: 1 TURNO | D27: TORNEP | E27: 0.47916667 | F27: 0.47916667 | G27: =E27-F27 -> 0 | L27: =SUM(H27:K27) -> 0 | M27: teste de vazão do poço, recuperação de nível, testes escalonados | O27: 104 | P27: 88007
A28: 46167 | B28: 88007 PP25067 - PARC DAS ARTES | D28: TORNEP | G28: =E28-F28 -> 0 | L28: =SUM(H28:K28) -> 0 | O28: 105 | P28: 88007
A29: 46168 | B29: 88007 PP25067 - PARC DAS ARTES | D29: TORNEP | G29: =E29-F29 -> 0 | L29: =SUM(H29:K29) -> 0 | O29: 106 | P29: 88007
A30: 46169 | B30: 88007 PP25067 - PARC DAS ARTES | C30: 1 TURNO | D30: TORNEP | G30: =E30-F30 -> 0 | L30: =SUM(H30:K30) -> 0 | O30: 107 | P30: 88007
A31: 46170 | B31: 88007 PP25067 - PARC DAS ARTES | D31: TORNEP | E31: 0.5 | F31: 0.41666667 | G31: =E31-F31 -> 0.083333333 | H31: 0.083333333 | L31: =SUM(H31:K31) -> 0.083333333 | M31: Deslocamento | O31: 108 | P31: 88007 | Q31: Retirada de bomba
A32: 46171 | B32: 88007 PP25067 - PARC DAS ARTES | C32: 1 TURNO | D32: TORNEP | E32: 0.41666667 | F32: 0.29166667 | G32: =E32-F32 -> 0.125 | H32: 0.125 | L32: =SUM(H32:K32) -> 0.125 | M32: Deslocamento/ a serviço do projeto | O32: 109 | P32: 88007 | Q32: Cimentação do poço/ Integração da Gel Eng
A33: 46172 | B33: 88007 PP25067 - PARC DAS ARTES | D33: TORNEP | G33: =E33-F33 -> 0 | L33: =SUM(H33:K33) -> 0 | O33: 110 | P33: 88007
A34: 46173 | B34: 88007 PP25067 - PARC DAS ARTES | D34: TORNEP | G34: =E34-F34 -> 0
E36: TOTAL | F36: TOTAL | G36: TOTAL | H36: TOTAL | I36: TOTAL | J36: TOTAL | K36: TOTAL
E37: =SUM(E4:E33) -> 12.972222 | F37: =SUM(F4:F33) -> 10.474306 | G37: =SUM(G4:G33) -> 2.4979167 | H37: =SUM(H4:H33) -> 0.89027778 | I37: =SUM(I4:I33) -> 1.5451389 | J37: =SUM(J4:J33) -> 0.0625 | K37: =SUM(K4:K33) -> 0
A40: RESUMO AUTOMÁTICO DE HORAS
A42: Total Horas do Projeto | D42: =SUM(E4:E33) -> 12.972222 | F42: =D42/11 -> 1.1792929 | G42: dias
A43: Total Horas Trabalhadas | D43: =SUM(F4:F33) -> 10.474306 | F43: =D43/11 -> 0.9522096 | G43: dias
A44: Total Horas Paradas | D44: =SUM(G4:G33) -> 2.4979167 | F44: =D44/11 -> 0.22708333 | G44: dias
A45: Total Horas DH-GEL Engenharia | D45: =SUM(H4:H33) -> 0.89027778 | F45: =D45/11 -> 0.080934343 | G45: dias
...

Sheet EQUIPAMENTOS
A1: CONTROLE DE HORAS PARADAS - ABRIL
A3: Data | B3: Projeto | C3: Equipe | D3: Equipamento | E3: Horário de: | F3: Horário até: | G3: Horas Paradas | H3: Motivo / Justificativa | I3: Responsável | J3: Horimetro Compressor
A4: 46077 | D4: Bomba Gardner | E4: 0.64930556 | F4: 0.76388889 | G4: =Tabela_Abril10[[#This Row],[Horário até:]]-Tabela_Abril10[[#This Row],[Horário de:]] -> 0.11458333 | H4: Manutenção | J4: 06/05 - chegou com 1850:30 -Terminou com 1885:04 =
A5: 46167 | D5: Bomba Duplex e Centrifuga | E5: 0.29166667 | F5: 0.4375 | G5: =Tabela_Abril10[[#This Row],[Horário até:]]-Tabela_Abril10[[#This Row],[Horário de:]] -> 0.14583333 | J5: =1850.3-1885.04 -> -34.74
D6: Bomba Duplex | E6: 0.45833333 | F6: 0.63194444 | G6: =Tabela_Abril10[[#This Row],[Horário até:]]-Tabela_Abril10[[#This Row],[Horário de:]] -> 0.17361111
A7: 46086 | D7: Martelo | G7: =Tabela_Abril10[[#This Row],[Horário até:]]-Tabela_Abril10[[#This Row],[Horário de:]] -> 0 | H7: martelo apresentou problemas, foi para manutenção no final do dia e retornou dia 07/03
A8: 46089 | D8: Martelo | G8: =Tabela_Abril10[[#This Row],[Horário até:]]-Tabela_Abril10[[#This Row],[Horário de:]] -> 0 | H8: apresentou probemas novamente após as 10:50
A9: 46091 | D9: Sonda | E9: 0.4375 | F9: 0.45833333 | G9: =Tabela_Abril10[[#This Row],[Horário até:]]-Tabela_Abril10[[#This Row],[Horário de:]] -> 0.020833333 | H9: embreagem da sonda para manutenção
A10: 46100 | D10: Underreamer | E10: 0.375 | F10: 0.47916667 | G10: =Tabela_Abril10[[#This Row],[Horário até:]]-Tabela_Abril10[[#This Row],[Horário de:]] -> 0.10416667 | H10: Manutenção
A11: 46101 | D11: Sonda | E11: 0.29166667 | F11: 0.70833333 | G11: =Tabela_Abril10[[#This Row],[Horário até:]]-Tabela_Abril10[[#This Row],[Horário de:]] -> 0.41666667 | H11: Compresor da sonda apresentou mal funcionamento
A12: 46105 | D12: Catarina | E12: 1.0104167 | F12: 1.0902778 | G12: =Tabela_Abril10[[#This Row],[Horário até:]]-Tabela_Abril10[[#This Row],[Horário de:]] -> 0.079861111 | H12: Trocando mola
A13: 46108 | D13: Ø 17 1/2" - martelo | E13: 0.875 | F13: 1.2916667 | G13: =Tabela_Abril10[[#This Row],[Horário até:]]-Tabela_Abril10[[#This Row],[Horário de:]] -> 0.41666667 | H13: Apresentou problemas
A14: 46109 | D14: Fole da embreagem | E14: 0.54166667 | F14: 0.79166667 | G14: =Tabela_Abril10[[#This Row],[Horário até:]]-Tabela_Abril10[[#This Row],[Horário de:]] -> 0.25
A15: 46110 | D15: Fole da embreagem | E15: 0.29166667 | F15: 0.375 | G15: =Tabela_Abril10[[#This Row],[Horário até:]]-Tabela_Abril10[[#This Row],[Horário de:]] -> 0.083333333
D16: Fole da embreagem | E16: 0.79166667 | F16: 1.2916667 | G16: =Tabela_Abril10[[#This Row],[Horário até:]]-Tabela_Abril10[[#This Row],[Horário de:]] -> 0.5
G17: =Tabela_Abril10[[#This Row],[Horário até:]]-Tabela_Abril10[[#This Row],[Horário de:]] -> 0
A18: 46122 | D18: Bomba Ensco | E18: 0.125 | F18: 0.25 | G18: =Tabela_Abril10[[#This Row],[Horário até:]]-Tabela_Abril10[[#This Row],[Horário de:]] -> 0.125
A19: 46124 | D19: Underreamer | E19: 0.875 | F19: 1.0416667 | G19: =Tabela_Abril10[[#This Row],[Horário até:]]-Tabela_Abril10[[#This Row],[Horário de:]] -> 0.16666667
A20: 46125 | D20: Sonda | E20: 0.75 | F20: 0.79166667 | G20: =Tabela_Abril10[[#This Row],[Horário até:]]-Tabela_Abril10[[#This Row],[Horário de:]] -> 0.041666667
A21: 46126 | D21: Bomba Ensco | E21: 0.64236111 | F21: 0.69444444 | G21: =Tabela_Abril10[[#This Row],[Horário até:]]-Tabela_Abril10[[#This Row],[Horário de:]] -> 0.052083333
D22: Bomba Ensco | E22: 0.034722222 | F22: 0.083333333 | G22: =Tabela_Abril10[[#This Row],[Horário até:]]-Tabela_Abril10[[#This Row],[Horário de:]] -> 0.048611111
D23: Fole da mesa | E23: 0.35416667 | F23: 0.55902778 | G23: =Tabela_Abril10[[#This Row],[Horário até:]]-Tabela_Abril10[[#This Row],[Horário de:]] -> 0.20486111
A24: 46127 | D24: Underreamer | E24: 1.0208333 | F24: 1.2916667 | G24: =Tabela_Abril10[[#This Row],[Horário até:]]-Tabela_Abril10[[#This Row],[Horário de:]] -> 0.27083333
A25: 46128 | D25: Underreamer | E25: 0.29166667 | F25: 0.39583333 | G25: =Tabela_Abril10[[#This Row],[Horário até:]]-Tabela_Abril10[[#This Row],[Horário de:]] -> 0.10416667
D26: Sonda | E26: 0.39583333 | F26: 0.64583333 | G26: =Tabela_Abril10[[#This Row],[Horário até:]]-Tabela_Abril10[[#This Row],[Horário de:]] -> 0.25
A27: 46130 | D27: Bomba Ensco | E27: 0.47916667 | F27: 0.64583333 | G27: =Tabela_Abril10[[#This Row],[Horário até:]]-Tabela_Abril10[[#This Row],[Horário de:]] -> 0.16666667
D28: Underreamer | E28: 0.64583333 | F28: 0.72916667 | G28: =Tabela_Abril10[[#This Row],[Horário até:]]-Tabela_Abril10[[#This Row],[Horário de:]] -> 0.083333333
G29: =Tabela_Abril10[[#This Row],[Horário até:]]-Tabela_Abril10[[#This Row],[Horário de:]] -> 0
G30: =Tabela_Abril10[[#This Row],[Horário até:]]-Tabela_Abril10[[#This Row],[Horário de:]] -> 0
G31: =Tabela_Abril10[[#This Row],[Horário até:]]-Tabela_Abril10[[#This Row],[Horário de:]] -> 0
G32: =Tabela_Abril10[[#This Row],[Horário até:]]-Tabela_Abril10[[#This Row],[Horário de:]] -> 0
G33: =Tabela_Abril10[[#This Row],[Horário até:]]-Tabela_Abril10[[#This Row],[Horário de:]] -> 0
G35: =SUM(G4:G33) -> 3.8194444
A37: RESUMO AUTOMÁTICO DE HORAS
A41: Total Horas Paradas - Manutenção | D41: =SUM(G4:G33) -> 3.8194444 | E41: Dias | F41: =D41/12 -> 0.31828704

Sheet PERFURAÇÃO
A1: CONTROLE DE PERFURAÇÃO
A3: Data | B3: Ferramenta | C3: De: | D3: Até: | E3: Quantidade Metros | F3: Tipo | G3: De | H3: Até | I3: Quantidade M Reaberto | J3: Horário Inicio | K3: Horário Término | L3: Tempo Perfuração | M3: Tempo Reabertura | N3: Diesel S10 | O3: Diesel S500 | P3: Observação Reabertura
A4: 46076 | B4: Ø 12 1/4" - martelo | C4: 0 | D4: 2 | E4: =Tabela_Fevereiro88[[#This Row],[Até:]]-Tabela_Fevereiro88[[#This Row],[De:]] -> 2 | F4: Perfuração | I4: =Tabela_Fevereiro88[[#This Row],[Até]]-Tabela_Fevereiro88[[#This Row],[De]] -> 0 | J4: 0.45486111 | K4: 0.47222222 | L4: =Tabela_Fevereiro88[[#This Row],[Horário Término]]-Tabela_Fevereiro88[[#This Row],[Horário Inicio]] -> 0.017361111
B5: Ø 12 1/4" - martelo | C5: 2 | D5: 3.3 | E5: =Tabela_Fevereiro88[[#This Row],[Até:]]-Tabela_Fevereiro88[[#This Row],[De:]] -> 1.3 | F5: Perfuração | I5: =Tabela_Fevereiro88[[#This Row],[Até]]-Tabela_Fevereiro88[[#This Row],[De]] -> 0 | J5: 0.54861111 | K5: 0.56944444 | L5: =Tabela_Fevereiro88[[#This Row],[Horário Término]]-Tabela_Fevereiro88[[#This Row],[Horário Inicio]] -> 0.020833333
B6: Ø 12 1/4" - martelo | C6: 3.3 | D6: 6.2 | E6: =Tabela_Fevereiro88[[#This Row],[Até:]]-Tabela_Fevereiro88[[#This Row],[De:]] -> 2.9 | F6: Perfuração | I6: =Tabela_Fevereiro88[[#This Row],[Até]]-Tabela_Fevereiro88[[#This Row],[De]] -> 0 | J6: 0.65277778 | K6: 0.74652778 | L6: =Tabela_Fevereiro88[[#This Row],[Horário Término]]-Tabela_Fevereiro88[[#This Row],[Horário Inicio]] -> 0.09375
A7: 46077 | B7: Ø 18" - martelo | C7: 6.2 | D7: 9.2 | E7: =Tabela_Fevereiro88[[#This Row],[Até:]]-Tabela_Fevereiro88[[#This Row],[De:]] -> 3 | F7: Perfuração | I7: =Tabela_Fevereiro88[[#This Row],[Até]]-Tabela_Fevereiro88[[#This Row],[De]] -> 0 | J7: 0.29166667 | K7: 0.54166667 | L7: =Tabela_Fevereiro88[[#This Row],[Horário Término]]-Tabela_Fevereiro88[[#This Row],[Horário Inicio]] -> 0.25 | P7: Atingiu Basalto
B8: Ø 17 1/2" - martelo | E8: =Tabela_Fevereiro88[[#This Row],[Até:]]-Tabela_Fevereiro88[[#This Row],[De:]] -> 0 | F8: Reabertura | G8: 0 | H8: 4 | I8: =Tabela_Fevereiro88[[#This Row],[Até]]-Tabela_Fevereiro88[[#This Row],[De]] -> 4 | L8: =Tabela_Fevereiro88[[#This Row],[Horário Término]]-Tabela_Fevereiro88[[#This Row],[Horário Inicio]] -> 0 | M8: 0.038194444 | P8: 14:40 as 15:35
A9: 46078 | B9: Ø 17 1/2" - martelo | E9: =Tabela_Fevereiro88[[#This Row],[Até:]]-Tabela_Fevereiro88[[#This Row],[De:]] -> 0 | F9: Reabertura | G9: 4 | H9: 4.25 | I9: =Tabela_Fevereiro88[[#This Row],[Até]]-Tabela_Fevereiro88[[#This Row],[De]] -> 0.25 | L9: =Tabela_Fevereiro88[[#This Row],[Horário Término]]-Tabela_Fevereiro88[[#This Row],[Horário Inicio]] -> 0 | M9: 0.020833333 | P9: 10:30 as 11:00
B10: Ø 17 1/2" - martelo | E10: =Tabela_Fevereiro88[[#This Row],[Até:]]-Tabela_Fevereiro88[[#This Row],[De:]] -> 0 | F10: Reabertura | G10: 4.25 | H10: 6.7 | I10: =Tabela_Fevereiro88[[#This Row],[Até]]-Tabela_Fevereiro88[[#This Row],[De]] -> 2.45 | L10: =Tabela_Fevereiro88[[#This Row],[Horário Término]]-Tabela_Fevereiro88[[#This Row],[Horário Inicio]] -> 0 | M10: 0.013888889
B11: Ø 17 1/2" - martelo | E11: =Tabela_Fevereiro88[[#This Row],[Até:]]-Tabela_Fevereiro88[[#This Row],[De:]] -> 0 | F11: Reabertura | G11: 6.7 | H11: 7.29 | I11: =Tabela_Fevereiro88[[#This Row],[Até]]-Tabela_Fevereiro88[[#This Row],[De]] -> 0.59 | L11: =Tabela_Fevereiro88[[#This Row],[Horário Término]]-Tabela_Fevereiro88[[#This Row],[Horário Inicio]] -> 0 | M11: 0.045138889
A12: 46079 | B12: Ø 30" - martelo | E12: =Tabela_Fevereiro88[[#This Row],[Até:]]-Tabela_Fevereiro88[[#This Row],[De:]] -> 0 | F12: Reabertura | G12: 0 | H12: 9 | I12: =Tabela_Fevereiro88[[#This Row],[Até]]-Tabela_Fevereiro88[[#This Row],[De]] -> 9 | L12: =Tabela_Fevereiro88[[#This Row],[Horário Término]]-Tabela_Fevereiro88[[#This Row],[Horário Inicio]] -> 0 | M12: 0.25347222 | P12: 10:25 as 16:30
A13: 46084 | B13: Ø 18" - martelo | C13: 9.2 | D13: 11 | E13: =Tabela_Fevereiro88[[#This Row],[Até:]]-Tabela_Fevereiro88[[#This Row],[De:]] -> 1.8 | F13: Perfuração | I13: =Tabela_Fevereiro88[[#This Row],[Até]]-Tabela_Fevereiro88[[#This Row],[De]] -> 0 | J13: 0.63888889 | K13: 0.65138889 | L13: =Tabela_Fevereiro88[[#This Row],[Horário Término]]-Tabela_Fevereiro88[[#This Row],[Horário Inicio]] -> 0.0125
B14: Ø 18" - martelo | C14: 11 | D14: 13.3 | E14: =Tabela_Fevereiro88[[#This Row],[Até:]]-Tabela_Fevereiro88[[#This Row],[De:]] -> 2.3 | F14: Perfuração | I14: =Tabela_Fevereiro88[[#This Row],[Até]]-Tabela_Fevereiro88[[#This Row],[De]] -> 0 | J14: 0.68263889 | K14: 0.73611111 | L14: =Tabela_Fevereiro88[[#This Row],[Horário Término]]-Tabela_Fevereiro88[[#This Row],[Horário Inicio]] -> 0.053472222
B15: Ø 18" - martelo | C15: 13.3 | D15: 14 | E15: =Tabela_Fevereiro88[[#This Row],[Até:]]-Tabela_Fevereiro88[[#This Row],[De:]] -> 0.7 | F15: Perfuração | I15: =Tabela_Fevereiro88[[#This Row],[Até]]-Tabela_Fevereiro88[[#This Row],[De]] -> 0 | J15: 0.75 | K15: 0.77083333 | L15: =Tabela_Fevereiro88[[#This Row],[Horário Término]]-Tabela_Fevereiro88[[#This Row],[Horário Inicio]] -> 0.020833333
A16: 46085 | B16: Ø 18" - martelo | C16: 14 | D16: 15.5 | E16: =Tabela_Fevereiro88[[#This Row],[Até:]]-Tabela_Fevereiro88[[#This Row],[De:]] -> 1.5 | F16: Perfuração | I16: =Tabela_Fevereiro88[[#This Row],[Até]]-Tabela_Fevereiro88[[#This Row],[De]] -> 0 | J16: 0.41666667 | K16: 0.43402778 | L16: =Tabela_Fevereiro88[[#This Row],[Horário Término]]-Tabela_Fevereiro88[[#This Row],[Horário Inicio]] -> 0.017361111
B17: Ø 18" - martelo | C17: 15.5 | D17: 22.5 | E17: =Tabela_Fevereiro88[[#This Row],[Até:]]-Tabela_Fevereiro88[[#This Row],[De:]] -> 7 | F17: Perfuração | I17: =Tabela_Fevereiro88[[#This Row],[Até]]-Tabela_Fevereiro88[[#This Row],[De]] -> 0 | J17: 0.52777778 | K17: 0.69444444 | L17: =Tabela_Fevereiro88[[#This Row],[Horário Término]]-Tabela_Fevereiro88[[#This Row],[Horário Inicio]] -> 0.16666667
B18: Ø 18" - martelo | C18: 22.5 | D18: 26 | E18: =Tabela_Fevereiro88[[#This Row],[Até:]]-Tabela_Fevereiro88[[#This Row],[De:]] -> 3.5 | F18: Perfuração | I18: =Tabela_Fevereiro88[[#This Row],[Até]]-Tabela_Fevereiro88[[#This Row],[De]] -> 0 | J18: 0.73611111 | K18: 0.77083333 | L18: =Tabela_Fevereiro88[[#This Row],[Horário Término]]-Tabela_Fevereiro88[[#This Row],[Horário Inicio]] -> 0.034722222
A19: 46086 | B19: Ø 18" - martelo | C19: 26 | D19: 29.54 | E19: =Tabela_Fevereiro88[[#This Row],[Até:]]-Tabela_Fevereiro88[[#This Row],[De:]] -> 3.54 | F19: Perfuração | I19: =Tabela_Fevereiro88[[#This Row],[Até]]-Tabela_Fevereiro88[[#This Row],[De]] -> 0 | J19: 0.36111111 | K19: 0.41666667 | L19: =Tabela_Fevereiro88[[#This Row],[Horário Término]]-Tabela_Fevereiro88[[#This Row],[Horário Inicio]] -> 0.055555556
A20: 46088 | B20: Ø 18" - martelo | C20: 29.54 | D20: 36.54 | E20: =Tabela_Fevereiro88[[#This Row],[Até:]]-Tabela_Fevereiro88[[#This Row],[De:]] -> 7 | F20: Perfuração | I20: =Tabela_Fevereiro88[[#This Row],[Até]]-Tabela_Fevereiro88[[#This Row],[De]] -> 0 | J20: 0.39236111 | K20: 0.44444444 | L20: =Tabela_Fevereiro88[[#This Row],[Horário Término]]-Tabela_Fevereiro88[[#This Row],[Horário Inicio]] -> 0.052083333
B21: Ø 18" - martelo | C21: 36.54 | D21: 43.46 | E21: =Tabela_Fevereiro88[[#This Row],[Até:]]-Tabela_Fevereiro88[[#This Row],[De:]] -> 6.92 | F21: Perfuração | I21: =Tabela_Fevereiro88[[#This Row],[Até]]-Tabela_Fevereiro88[[#This Row],[De]] -> 0 | J21: 0.54166667 | K21: 0.61111111 | L21: =Tabela_Fevereiro88[[#This Row],[Horário Término]]-Tabela_Fevereiro88[[#This Row],[Horário Inicio]] -> 0.069444444
B22: Ø 18" - martelo | C22: 43.46 | D22: 47 | E22: =Tabela_Fevereiro88[[#This Row],[Até:]]-Tabela_Fevereiro88[[#This Row],[De:]] -> 3.54 | F22: Perfuração | I22: =Tabela_Fevereiro88[[#This Row],[Até]]-Tabela_Fevereiro88[[#This Row],[De]] -> 0 | J22: 0.73611111 | K22: 0.77430556 | L22: =Tabela_Fevereiro88[[#This Row],[Horário Término]]-Tabela_Fevereiro88[[#This Row],[Horário Inicio]] -> 0.038194444
A23: 46089 | B23: Ø 18" - martelo | C23: 47 | D23: 50 | E23: =Tabela_Fevereiro88[[#This Row],[Até:]]-Tabela_Fevereiro88[[#This Row],[De:]] -> 3 | F23: Perfuração | I23: =Tabela_Fevereiro88[[#This Row],[Até]]-Tabela_Fevereiro88[[#This Row],[De]] -> 0 | J23: 0.375 | K23: 0.40625 | L23: =Tabela_Fevereiro88[[#This Row],[Horário Término]]-Tabela_Fevereiro88[[#This Row],[Horário Inicio]] -> 0.03125
B24: Ø 18" - martelo | C24: 50 | D24: 52 | E24: =Tabela_Fevereiro88[[#This Row],[Até:]]-Tabela_Fevereiro88[[#This Row],[De:]] -> 2 | F24: Perfuração | I24: =Tabela_Fevereiro88[[#This Row],[Até]]-Tabela_Fevereiro88[[#This Row],[De]] -> 0 | J24: 0.4375 | K24: 0.45138889 | L24: =Tabela_Fevereiro88[[#This Row],[Horário Término]]-Tabela_Fevereiro88[[#This Row],[Horário Inicio]] -> 0.013888889
A25: 46090 | B25: Ø 18" - martelo | C25: 52 | D25: 60 | E25: =Tabela_Fevereiro88[[#This Row],[Até:]]-Tabela_Fevereiro88[[#This Row],[De:]] -> 8 | F25: Perfuração | I25: =Tabela_Fevereiro88[[#This Row],[Até]]-Tabela_Fevereiro88[[#This Row],[De]] -> 0 | J25: 0.35763889 | K25: 0.4375 | L25: =Tabela_Fevereiro88[[#This Row],[Horário Término]]-Tabela_Fevereiro88[[#This Row],[Horário Inicio]] -> 0.079861111
B26: Ø 18" - martelo | C26: 60 | D26: 63 | E26: =Tabela_Fevereiro88[[#This Row],[Até:]]-Tabela_Fevereiro88[[#This Row],[De:]] -> 3 | F26: Perfuração | I26: =Tabela_Fevereiro88[[#This Row],[Até]]-Tabela_Fevereiro88[[#This Row],[De]] -> 0 | J26: 0.57638889 | K26: 0.58680556 | L26: =Tabela_Fevereiro88[[#This Row],[Horário Término]]-Tabela_Fevereiro88[[#This Row],[Horário Inicio]] -> 0.010416667
A27: 46091 | B27: Ø 18" - martelo | C27: 63 | D27: 68 | E27: =Tabela_Fevereiro88[[#This Row],[Até:]]-Tabela_Fevereiro88[[#This Row],[De:]] -> 5 | F27: Perfuração | I27: =Tabela_Fevereiro88[[#This Row],[Até]]-Tabela_Fevereiro88[[#This Row],[De]] -> 0 | J27: 0.32638889 | K27: 0.37152778 | L27: =Tabela_Fevereiro88[[#This Row],[Horário Término]]-Tabela_Fevereiro88[[#This Row],[Horário Inicio]] -> 0.045138889 | P27: Pegou arenito entre 67,0 e 68,0 metros
A28: 46103 | B28: Ø 17 1/2" - martelo | C28: 68 | D28: 94 | E28: =Tabela_Fevereiro88[[#This Row],[Até:]]-Tabela_Fevereiro88[[#This Row],[De:]] -> 26 | F28: Perfuração | I28: =Tabela_Fevereiro88[[#This Row],[Até]]-Tabela_Fevereiro88[[#This Row],[De]] -> 0 | J28: 0.49305556 | K28: 0.72847222 | L28: =Tabela_Fevereiro88[[#This Row],[Horário Término]]-Tabela_Fevereiro88[[#This Row],[Horário Inicio]] -> 0.23541667
A29: 46104 | B29: Ø 17 1/2" - martelo | C29: 94 | D29: 95.26 | E29: =Tabela_Fevereiro88[[#This Row],[Até:]]-Tabela_Fevereiro88[[#This Row],[De:]] -> 1.26 | F29: Perfuração | I29: =Tabela_Fevereiro88[[#This Row],[Até]]-Tabela_Fevereiro88[[#This Row],[De]] -> 0 | J29: 0.34375 | K29: 0.35416667 | L29: =Tabela_Fevereiro88[[#This Row],[Horário Término]]-Tabela_Fevereiro88[[#This Row],[Horário Inicio]] -> 0.010416667
B30: Ø 17 1/2" - martelo | C30: 95.26 | D30: 126 | E30: =Tabela_Fevereiro88[[#This Row],[Até:]]-Tabela_Fevereiro88[[#This Row],[De:]] -> 30.74 | F30: Perfuração | I30: =Tabela_Fevereiro88[[#This Row],[Até]]-Tabela_Fevereiro88[[#This Row],[De]] -> 0 | J30: 0.4375 | K30: 0.79513889 | L30: =Tabela_Fevereiro88[[#This Row],[Horário Término]]-Tabela_Fevereiro88[[#This Row],[Horário Inicio]] -> 0.35763889
A31: 46105 | B31: Ø 17 1/2" - martelo | C31: 126 | D31: 142.88 | E31: =Tabela_Fevereiro88[[#This Row],[Até:]]-Tabela_Fevereiro88[[#This Row],[De:]] -> 16.88 | F31: Perfuração | I31: =Tabela_Fevereiro88[[#This Row],[Até]]-Tabela_Fevereiro88[[#This Row],[De]] -> 0 | J31: 0.72222222 | K31: 0.8125 | L31: =Tabela_Fevereiro88[[#This Row],[Horário Término]]-Tabela_Fevereiro88[[#This Row],[Horário Inicio]] -> 0.090277778
B32: Ø 17 1/2" - martelo | C32: 142.88 | D32: 156.64 | E32: =Tabela_Fevereiro88[[#This Row],[Até:]]-Tabela_Fevereiro88[[#This Row],[De:]] -> 13.76 | F32: Perfuração | I32: =Tabela_Fevereiro88[[#This Row],[Até]]-Tabela_Fevereiro88[[#This Row],[De]] -> 0 | J32: 0.85416667 | K32: 1.0104167 | L32: =Tabela_Fevereiro88[[#This Row],[Horário Término]]-Tabela_Fevereiro88[[#This Row],[Horário Inicio]] -> 0.15625
B33: Ø 17 1/2" - martelo | C33: 156.64 | D33: 169.72 | E33: =Tabela_Fevereiro88[[#This Row],[Até:]]-Tabela_Fevereiro88[[#This Row],[De:]] -> 13.08 | F33: Perfuração | I33: =Tabela_Fevereiro88[[#This Row],[Até]]-Tabela_Fevereiro88[[#This Row],[De]] -> 0 | J33: 1.0902778 | K33: 1.2708333 | L33: =Tabela_Fevereiro88[[#This Row],[Horário Término]]-Tabela_Fevereiro88[[#This Row],[Horário Inicio]] -> 0.18055556
A34: 46106 | B34: Ø 17 1/2" - martelo | C34: 169.72 | D34: 206 | E34: =Tabela_Fevereiro88[[#This Row],[Até:]]-Tabela_Fevereiro88[[#This Row],[De:]] -> 36.28 | F34: Perfuração | I34: =Tabela_Fevereiro88[[#This Row],[Até]]-Tabela_Fevereiro88[[#This Row],[De]] -> 0 | J34: 0.29166667 | K34: 0.79166667 | L34: =Tabela_Fevereiro88[[#This Row],[Horário Término]]-Tabela_Fevereiro88[[#This Row],[Horário Inicio]] -> 0.5
B35: Ø 17 1/2" - martelo | C35: 206 | D35: 210 | E35: =Tabela_Fevereiro88[[#This Row],[Até:]]-Tabela_Fevereiro88[[#This Row],[De:]] -> 4 | F35: Perfuração | I35: =Tabela_Fevereiro88[[#This Row],[Até]]-Tabela_Fevereiro88[[#This Row],[De]] -> 0 | J35: 0.79166667 | K35: 0.81944444 | L35: =Tabela_Fevereiro88[[#This Row],[Horário Término]]-Tabela_Fevereiro88[[#This Row],[Horário Inicio]] -> 0.027777778
B36: Ø 17 1/2" - martelo | C36: 210 | D36: 217 | E36: =Tabela_Fevereiro88[[#This Row],[Até:]]-Tabela_Fevereiro88[[#This Row],[De:]] -> 7 | F36: Perfuração | I36: =Tabela_Fevereiro88[[#This Row],[Até]]-Tabela_Fevereiro88[[#This Row],[De]] -> 0 | J36: 0.91666667 | K36: 1 | L36: =Tabela_Fevereiro88[[#This Row],[Horário Término]]-Tabela_Fevereiro88[[#This Row],[Horário Inicio]] -> 0.083333333
B37: Ø 17 1/2" - martelo | C37: 217 | D37: 228 | E37: =Tabela_Fevereiro88[[#This Row],[Até:]]-Tabela_Fevereiro88[[#This Row],[De:]] -> 11 | F37: Perfuração | I37: =Tabela_Fevereiro88[[#This Row],[Até]]-Tabela_Fevereiro88[[#This Row],[De]] -> 0 | J37: 1.1180556 | K37: 1.2916667 | L37: =Tabela_Fevereiro88[[#This Row],[Horário Término]]-Tabela_Fevereiro88[[#This Row],[Horário Inicio]] -> 0.17361111
A38: 46107 | B38: Ø 17 1/2" - martelo | C38: 228 | D38: 263 | E38: =Tabela_Fevereiro88[[#This Row],[Até:]]-Tabela_Fevereiro88[[#This Row],[De:]] -> 35 | F38: Perfuração | I38: =Tabela_Fevereiro88[[#This Row],[Até]]-Tabela_Fevereiro88[[#This Row],[De]] -> 0 | J38: 0.29166667 | K38: 0.79166667 | L38: =Tabela_Fevereiro88[[#This Row],[Horário Término]]-Tabela_Fevereiro88[[#This Row],[Horário Inicio]] -> 0.5
A39: 46108 | B39: Ø 17 1/2" - martelo | C39: 263 | D39: 288.9 | E39: =Tabela_Fevereiro88[[#This Row],[Até:]]-Tabela_Fevereiro88[[#This Row],[De:]] -> 25.9 | F39: Perfuração | I39: =Tabela_Fevereiro88[[#This Row],[Até]]-Tabela_Fevereiro88[[#This Row],[De]] -> 0 | J39: 0.29166667 | K39: 0.79166667 | L39: =Tabela_Fevereiro88[[#This Row],[Horário Término]]-Tabela_Fevereiro88[[#This Row],[Horário Inicio]] -> 0.5
B40: Ø 17 1/2" - martelo | C40: 288.9 | D40: 289.1 | E40: =Tabela_Fevereiro88[[#This Row],[Até:]]-Tabela_Fevereiro88[[#This Row],[De:]] -> 0.2 | F40: Perfuração | I40: =Tabela_Fevereiro88[[#This Row],[Até]]-Tabela_Fevereiro88[[#This Row],[De]] -> 0 | J40: 0.79166667 | K40: 0.875 | L40: =Tabela_Fevereiro88[[#This Row],[Horário Término]]-Tabela_Fevereiro88[[#This Row],[Horário Inicio]] -> 0.083333333 | P40: Problema na ferramenta
A41: 46111 | B41: Ø 17 1/2" - martelo | C41: 289.1 | D41: 289.2 | E41: =Tabela_Fevereiro88[[#This Row],[Até:]]-Tabela_Fevereiro88[[#This Row],[De:]] -> 0.1 | F41: Perfuração | I41: =Tabela_Fevereiro88[[#This Row],[Até]]-Tabela_Fevereiro88[[#This Row],[De]] -> 0 | J41: 0.52083333 | K41: 0.70833333 | L41: =Tabela_Fevereiro88[[#This Row],[Horário Término]]-Tabela_Fevereiro88[[#This Row],[Horário Inicio]] -> 0.1875 | P41: Problema no sistema de ar do fole
...

Sheet QUÍMICOS
A1: CONTROLE DE QUIMICOS | I1: DASHBOARD - CONSUMO DE QUIMICOS
A3: Data | B3: CMC | C3: Goma Xantana | D3: Barilha | E3: Hexa T | F3: Bentonita | G3: Motivo / Justificativa
A4: 46102 | B4: 250 | D4: 50 | F4: 250
A5: 46103 | B5: 60 | D5: 6 | F5: 250
A6: 46104 | B6: 50 | D6: 3.5
A7: 46105 | B7: 25 | C7: 25 | D7: 4
A8: 46106 | B8: 75 | D8: 23
A9: 46107 | B9: 75 | D9: 5
A10: 46108 | C10: 62 | D10: 4
A11: 46111 | B11: 50 | C11: 50 | D11: 50
A12: 46112 | B12: 50 | D12: 25
B13: 35 | C13: 25 | D13: 50
A14: 46113 | B14: 25 | D14: 15
A15: 46120 | B15: 75 | C15: 75 | D15: 63
A16: 46121 | B16: 75 | C16: 25 | D16: 75
B17: 75 | C17: 25 | D17: 50
A18: 46122 | B18: 25 | C18: 50 | D18: 25
A19: 46123 | B19: 75 | C19: 75 | D19: 8
A20: 46124 | B20: 25 | C20: 25 | D20: 13
A21: 46125 | B21: 82 | C21: 75 | D21: 38
A22: 46126 | B22: 100 | D22: 25
B23: 100 | C23: 100 | D23: 25
A24: 46128 | B24: 100 | C24: 75
B25: 250 | C25: 75 | D25: 18
A26: 46129 | B26: 75 | C26: 50 | D26: 25
A27: 46130 | B27: 175 | C27: 50 | D27: 29
D28: 25
A29: 46131 | B29: 150 | C29: 25 | D29: 181
B30: 50 | D30: 15
A31: 46133 | B31: 75 | C31: 50 | D31: 8
A32: 46141 | E32: 200
A33: 46143 | E33: 25
A34: 46144 | E34: 175
A36: Quimicos | B36: CMC | C36: Goma X | D36: Barrilha | E36: Hexa T | F36: Bentonita
A37: Planejado | B37: 486.36 | C37: 0 | D37: 3.65 | E37: 341.28 | F37: 21375
A38: Realizado | B38: =SUM(B4:B35) -> 2202 | C38: =SUM(C5:C33) -> 937 | D38: =SUM(D4:D33) -> 858.5 | E38: =SUM(E32:E35) -> 400 | F38: =SUM(F4:F18) -> 500
A39: Imprevisto | B39: =B38-B37 -> 1715.64 | C39: =C38-C37 -> 937 | D39: =D38-D37 -> 854.85 | E39: =E38-E37 -> 58.72
A40: Porcentagem | B40: =B38/B37 -> 4.5275105 | D40: =D38/D37 -> 235.20548 | E40: =E38/E37 -> 1.1720581 | F40: =F38/F37 -> 0.023391813
A41: Status | B41: =IF(B38>B37,"ESTOURADO",IF(B39>=0.7,"ALERTA","OK")) -> ESTOURADO | C41: =IF(C38>C37,"ESTOURADO",IF(C39>=0.7,"ALERTA","OK")) -> ESTOURADO | D41: =IF(D38>D37,"ESTOURADO",IF(D39>=0.7,"ALERTA","OK")) -> ESTOURADO | E41: =IF(E38>E37,"ESTOURADO",IF(E39>=0.7,"ALERTA","OK")) -> ESTOURADO | F41: =IF(F38>F37,"ESTOURADO",IF(F39>=0.7,"ALERTA","OK")) -> OK

Sheet EQUIPAMENTOS LOCADOS
A1: CONTROLE DE HORAS TRABALHADAS X PARADAS
A3: Data | B3: Projeto | C3: Fornecedor | D3: Equipamento | E3: Previsto | F3: Realizado | G3: Dias imprevisto | H3: Porcentagem % | I3: Status | J3: Parada DH_GEL | K3: Parada Citrosuco | L3: Parada Chuva | M3: Outros Motivos | N3: Motivo / Justificativa | O3: Horario Inicial | P3: Horario Final | Q3: Total Horas dia
E34: TOTAL DIAS PREVISTO | F34: TOTAL DIAS REALIZADOS | G34: TOTAL | H34: % | I34: STATUS | Q34: TOTAL
E35: =E4 -> 0 | F35: =SUM(F4:F23) -> 0 | G35: =Tabela_Fevereiro7[[#This Row],[Realizado]]-Tabela_Fevereiro7[[#This Row],[Previsto]] -> 0 | H35: =Tabela_Fevereiro7[[#This Row],[Realizado]]/Tabela_Fevereiro7[[#This Row],[Previsto]] -> #DIV/0! | I35: =IF(F35>E35,"ESTOURADO",IF(F33>=0.7,"ALERTA","OK")) -> OK | Q35: =SUM(Q4:Q33) -> 0
A37: RESUMO AUTOMÁTICO DE HORAS
A39: Total Dias Previsto | D39: =SUM(E4:E33) -> 0 | F39: =D39/24 -> 0 | G39: dias
A40: Total dias Imprevisto | D40: =SUM(F4:F33) -> 0 | F40: =D40/24 -> 0 | G40: dias
A41: Margem Imprevista | D41: =G35 -> 0 | F41: =D41/24 -> 0 | G41: dias
B52: ver se coloca os equipamentos da DH tambem para fazer contagem de dias parados por problemas de manutenção separado?

Sheet DASHBOARD PERFURAÇÃO
A1: DASHBOARD - CONTROLE DE PERFURAÇÃO

Sheet DASHBOARD
A1: DASHBOARD - CONTROLE DE HORAS PARADAS
A5: Horas Totais | B5: =SUM('Fevereiro '!D29+Março!D41+Abril!D39+'Maio '!D42) -> 67.555556 | D5: Categoria | E5: Horas
A6: Horas Trabalhadas | B6: =SUM('Fevereiro '!D30+Março!D42+Abril!D40+'Maio '!D43) -> 45.080556 | D6: DH-GEL ENGENHARIA | E6: =B8 -> 8.3868056
A7: Horas Paradas | B7: =SUM('Fevereiro '!D31+Março!D43+Abril!D41+'Maio '!D44) -> 22.475 | D7: PARC DAS ARTES | E7: =B9 -> 9.7534722
A8: Parada DH-GEL ENGENHARIA | B8: =SUM('Fevereiro '!D32+Março!D44+Abril!D42+'Maio '!D45) -> 8.3868056 | D8: Chuva | E8: =B10 -> 0.32847222
A9: Parada PARC DAS ARTES | B9: =SUM('Fevereiro '!D33+Março!D45+Abril!D43+'Maio '!D46) -> 9.7534722 | D9: Mecânica | E9: =B11 -> 4.0201389
A10: Parada Chuva | B10: =SUM('Fevereiro '!D34+Março!D46+Abril!D44+'Maio '!D47) -> 0.32847222
A11: Parada Mecânica | B11: =SUM('Fevereiro '!D35+Março!D47+Abril!D45+'Maio '!D48) -> 4.0201389
D12: Mensal | E12: Trabalhada
D13: Fevereiro | E13: =SUM('Fevereiro '!D30) -> 4.8451389
D14: Março | E14: =SUM(Março!D42) -> 11.177083
A15: Tipo | B15: Horas | D15: Abril | E15: =SUM(Abril!D40) -> 18.584028
A16: DH-GEL ENGENHARIA | B16: =B8 -> 8.3868056 | D16: Maio | E16: =SUM('Maio '!D43) -> 10.474306
A17: PARC DAS ARTES | B17: =B9 -> 9.7534722
A18: Chuva | B18: =B10 -> 0.32847222
A19: Parada Mecânica | B19: =B11 -> 4.0201389

Sheet DISTRIBUIÇÃO DE HORAS PARADAS
A1: HORAS - TOTAL DE PARALIZAÇÃO DO PROJETO
A4: Parc das artes | B4: Horas | C4: Dias | E4: DH-GEL ENGENHARIA | F4: Horas | G4: Dias
A5: Administrativo | B5: =SUM('Fevereiro '!I22+Abril!I32+'Maio '!I7+'Maio '!I8+'Maio '!I9+'Maio '!I10+'Maio '!I26) -> 1.5868056 | C5: =B5/10 -> 0.15868056 | E5: Falta de Equipe/Administrativo | F5: 7.5048611 | G5: =F5/10 -> 0.75048611
A6: Equipamento | B6: =SUM('Maio '!I16) -> 0.16666667 | C6: =B6/10 -> 0.016666667 | E6: Manutenção de Equipamentos | F6: =DASHBOARD!B11 -> 4.0201389 | G6: =F6/10 -> 0.40201389
A7: Materiais | B7: =SUM(Março!I37) -> 8 | C7: =B7/10 -> 0.8 | E7: Chuva | F7: =DASHBOARD!B10 -> 0.32847222 | G7: =F7/10 -> 0.032847222
E8: Materiais | F8: ='Fevereiro '!H7+Março!H22+Abril!H26+'Fevereiro '!H6 -> 0.88194444 | G8: =F8/10 -> 0.088194444

Sheet DASHBOARD MENSAL
A1: PORCENTAGEM MENSAL DE PRODUTIVIDADE DO PROJETO
A4: Mês | B4: Horas Trabalhadas | C4: Horas Paradas
A5: Fevereiro | B5: =SUM('Fevereiro '!D30) -> 4.8451389 | C5: =SUM('Fevereiro '!D31) -> 1.8701389
A6: Março | B6: =SUM(Março!D42) -> 11.177083 | C6: =SUM(Março!D43) -> 11.118056
A7: Abril | B7: =SUM(Abril!D40) -> 18.584028 | C7: =SUM(Abril!D41) -> 6.9888889
A8: Maio | B8: =SUM('Maio '!D43) -> 10.474306 | C8: =SUM('Maio '!D44) -> 2.4979167

Sheet DASHBOARD GERAL DE EXECUÇÃO
A1: DIAS - TOTAL GERAL DO PROJETO
A4: Mês | B4: Inicio | C4: Previsto | D4: Termino | E4: Total Dias Realizados | F4: Total Dias Previsto | G4: Total Dias De Atraso | H4: Porcentagem de Atraso
A5: PARC DAS ARTES | B5: 46062 | C5: 46094 | D5: 46166 | E5: =SUM(D5-B5) -> 104 | F5: =SUM(C5-B5) -> 32 | G5: =SUM(E5-F5) -> 72 | H5: =(G5/E5) -> 0.69230769
G8: Dias Efetivos de Operação | H8: Horas | J8: Dias de Operações
G9: Horas Totais | H9: =SUM('Fevereiro '!D29+Março!D41+Abril!D39+'Maio '!D42) -> 67.555556 | J9: =H9 -> 67.555556
G10: Horas Trabalhadas | H10: =SUM('Fevereiro '!D30+Março!D42+Abril!D40+'Maio '!D43) -> 45.080556 | J10: =H10 -> 45.080556
G11: Horas Paradas | H11: =SUM('Fevereiro '!D31+Março!D43+Abril!D41+'Maio '!D44) -> 22.475 | J11: =H11 -> 22.475
G12: Parada DH-GEL ENGENHARIA | H12: =SUM('Fevereiro '!D32+Março!D44+Abril!D42+'Maio '!D45) -> 8.3868056 | J12: =H12 -> 8.3868056
