Workbook

Sheet Projeto
A3: PROJETO DO POÇO

Sheet Perfuração Cardwell
C2: CUSTEIO PERFURAÇÃO
C3: CARDWELL (24h) - 3 equipes 14x7
A6: LEGENDA | D6: DADOS | G6: POÇO | I6: DESLOCAMENTOS | L6: FONTE | M6: NOTAS
B7: Células a serem preenchidas, conforme projeto/internamente | C7: Cliente: | D7: SANEPAR | F7: Prof. (m) | G7: 870 | I7: Campinas (km) | J7: 440 | L7: RotaMapas | M7: Base de saída dos transportes x Obra
B8: Responsabilidades Contratante/Contratada | C8: Município: | D8: Cornélio Procópio/PR | F8: N.E. (m) | I8: São Paulo (km) | J8: 464 | L8: RotaMapas | M8: Base de saída de equipe de perfuração x Obra
A9: - | B9: Itens direcionados ao Faturamento Direto/Preço de venda dos materiais | C9: Endereço: | D9: Rua dos Expedicionários S/N | F9: N.D. (m) | G9: 280 | I9: Araraquara (km) | J9: 337 | L9: RotaMapas | M9: Galpão (DH) x obra
A10: - | B10: Preço de venda do poço | F10: Q (m³/h) | G10: 300 | I10: Jundiaí (km) | J10: 439 | L10: RotaMapas | M10: Perfil Master (perfilagem) x obra
C11: PRAZO OBRA | D11: =$I$42 -> 100 | F11: S (m) | I11: Ribeirão Bonito (km) | J11: 325 | L11: RotaMapas | M11: Locavem (compressor) x obra
A13: CRONOGRAMA ESTIMADO
A14: ITEM | B14: 1. SERVIÇOS | I14: DIAS (3 EQUIPES) | J14: OPERAÇÃO SONDA
A15: 1.1 | B15: DTM (mobilização e desmobilização) - cada operação em média 6 horas | I15: 8 | L15: Estimado | M15: Dias de DTM deve ser pactuado com operação, a depender da distância de deslocamento. Considera-se em média de 3 a 5 dias.
A16: 1.2 | B16: Instalação do Canteiro de Obras, Tanques de Lama, Canaletas, etc. | I16: 5 | L16: Estimado | M16: 5 dias em média para instalação do canteiro
A17: METODOLOGIA | C17: Ø" Perfuração | D17: Ø" Revestimento | E17: Metragem inicial | F17: Metragem final | G17: Metragem total | H17: Avanço | L17: Estimado
A18: 1.3 | B18: Perfuração Solo Sedimentos - Rotativa | C18: 26 | D18: 20 | E18: 0 | F18: 11.5 | G18: =F18-E18 -> 11.5 | H18: 10 | I18: =ROUNDUP(G18/H18,0) -> 2 | J18: =I18 -> 2 | L18: Estimado
A19: 1.4 | B19: Instalação do Tubo de Boca | C19: =$C$18 -> 26 | D19: =$D$18 -> 20 | E19: =$E$18 -> 0 | F19: =$F$18 -> 11.5 | G19: =F19-E19 -> 11.5 | H19: 10 | I19: =ROUNDUP(G19/H19,0) -> 2 | J19: =I19 -> 2 | L19: Estimado
A20: 1.5 | B20: Cimentação do Tubo de Boca e Cura | C20: =$C$18 -> 26 | D20: =E18 -> 0 | E20: =$E$19 -> 0 | F20: =$F$19 -> 11.5 | G20: =F20-E20 -> 11.5 | H20: 10 | I20: =ROUNDUP(G20/H20,0) -> 2 | J20: =I20 -> 2 | L20: Estimado
A21: 1.6 | B21: Perfuração Basalto - Rotopneumática | C21: 18 | D21: 14 | E21: =$F$18 -> 11.5 | F21: 150 | G21: =F21-E21 -> 138.5 | H21: 50 | I21: =ROUNDUP(G21/H21,0) -> 3 | J21: =I21 -> 3 | L21: Estimado | M21: Geralmente utilizamos Rotopneumático quando o tubo de boca é instalado em profundidades "rasas". A partir de 70 metros é possível considerar o método rotativo, porém necessário pactuar com operações. Para roto, faz-se ideal considerar até 150m para não ultrapassar a efetividade da sonda. Para 18" pode-se considerar 50 metros por dia.
A22: 1.7 | B22: Manobra troca do sistema de perfuração (broca) | I22: 1 | J22: =I22 -> 1 | L22: Estimado
A23: 1.8 | B23: Perfuração Basalto - Rotativa | C23: 17.5 | D23: 14 | E23: =$F$21 -> 150 | F23: 400 | G23: =F23-E23 -> 250 | H23: 15 | I23: =ROUNDUP(G23/H23,0) -> 17 | J23: =I23 -> 17 | L23: Estimado | M23: Pactuar com operações. Para 17 1/2" pode-se considerar 15 metros.
A24: 1.8 | B24: Perfuração Basalto - Rotativa | C24: 17.5 | D24: 10 | E24: =F23 -> 400 | F24: 750 | G24: =F24-E24 -> 350 | H24: 15 | I24: =ROUNDUP(G24/H24,0) -> 24 | J24: =I24 -> 24 | L24: Estimado | M24: Pactuar com operações. Para 17 1/2" pode-se considerar 15 metros.
A25: 1.9 | B25: Manobra troca do sistema de perfuração + preparação do fluido à base de CMC | I25: 1 | J25: =I25 -> 1 | L25: Estimado
A26: 1.10 | B26: Perfuração Arenito - Rotativa | C26: 17.5 | D26: 8 | E26: =F24 -> 750 | F26: 870 | G26: =F26-E26 -> 120 | H26: 35 | I26: =ROUNDUP(G26/H26,0) -> 4 | J26: =I26 -> 4 | L26: Estimado | M26: Pactuar com operações. Para perfuração em 17 1/2" pode considerar 50 metros por dia.
A27: 1.11 | B27: Perfilagem Geofísica (Multi-Função + Sônico) | I27: 1 | J27: =I27 -> 1 | L27: Estimado | M27: Sempre pactuar a necessidade de separar em duas corridas a Perfilagem Geofísica, caso houver Reabertura.
A28: 1.12 | B28: Manobra troca do sistema de perfuração (broca) | I28: 1 | J28: =I28 -> 1 | L28: Estimado
A29: 1.13 | B29: Perfuração Arenito (REABERTURA) - Rotativa | C29: 20 | D29: 8 | E29: =E26 -> 750 | F29: =F26 -> 870 | G29: =F29-E29 -> 120 | H29: 30 | I29: =ROUNDUP(G29/H29,0) -> 4 | J29: =I29 -> 4 | L29: Estimado
A30: 1.14 | B30: Perfilagem Geofísica (Cáliper + Inclinação) | I30: 1 | J30: =I30 -> 1 | L30: Estimado | M30: Sempre pactuar a necessidade de separar em duas corridas de Perfilagem Geofísica, caso houver Reabertura.
A31: 1.15 | B31: Condicionamento da Lama | I31: 1 | J31: =I31 -> 1 | L31: Estimado | M31: Em média 1,0 a 1,5 dia. Pactuar internamente ou basear em projeto, caso houver.
A32: 1.16 | B32: Descida do Revestimento | E32: 0 | F32: =$G$7 -> 870 | G32: =F32-E32 -> 870 | H32: 400 | I32: =ROUNDUP(G32/H32,0) -> 3 | J32: =I32 -> 3 | L32: Estimado | M32: Em média 1,0 a 1,5 dia. Pactuar internamente ou basear em projeto, caso houver.
A33: 1.17 | B33: Descida e condicionamento do Pré-Filtro | E33: 0 | F33: =$G$7 -> 870 | G33: =F33-E33 -> 870 | H33: 400 | I33: =ROUNDUP(G33/H33,0) -> 3 | J33: =I33 -> 3 | L33: Estimado | M33: Em média 2 bags de pré-filtro por hora
A34: 1.18 | B34: Instalação e retirada do Air-Lift | E34: Metragem Total | G34: =$G$7 -> 870 | H34: 870 | I34: =ROUNDUP(G34/H34,0) -> 1 | J34: =I34 -> 1 | L34: Estimado | N34: Considerar a metragem total do poço.
A35: 1.19 | B35: Desenvolvimento - Sistema Air-lift (12 horas/dia) | E35: Quantidade de horas | G35: 24 | H35: 10 | I35: =ROUNDUP(G35/H35,0) -> 3 | J35: =I35 -> 3 | L35: Estimado | M35: Considera-se avanço de 10h devido a duração/dia de funcionamento ideal do compressor.
A36: 1.20 | B36: Instalação e retirada do conjunto moto-bomba | E36: Profundidade de instalação | G36: =IF($G$9>0,$G$9+ 20, 0.7*$G$7) -> 300 | H36: 300 | I36: =G36/H36 -> 1 | J36: =I36 -> 1 | L36: Estimado | M36: Normalmente considera-se 1 dia a instalação do conjunto motobomba. Pactuar internamente ou basear em projeto, caso houver.
A37: 1.21 | B37: Desenvolvimento - Bomba submersa | E37: Quantidade de horas | G37: 24 | H37: 24 | I37: =ROUNDUP(G37/H37,1) -> 1 | J37: =I37 -> 1 | L37: Estimado
A38: 1.22 | B38: Teste de Vazão | E38: Quantidade de horas | G38: 100 | H38: 24 | I38: =ROUNDUP(G38/H38,1) -> 4.2 | J38: =I38 -> 4.2 | L38: Estimado
A39: 1.23 | B39: Perfilagem Óptica | I39: 1 | J39: =I39 -> 1 | L39: Estimado
A40: 1.24 | B40: Desmontagem da Sonda | I40: =I16 -> 5 | J40: =I40 -> 5 | L40: Estimado
A41: 1.25 | B41: DSR - Descanso aos Domingos (Sim:1 Não:0) | G41: (Sim:1 Não:0) | H41: 0 | I41: =ROUNDUP(SUM(I16,I18:I40)/6,0)*H41 -> 0 | J41: =I41 -> 0 | L41: Estimado
A42: SUBTOTAL | B42: PRAZOS (DIAS) | I42: =ROUNDUP(SUM(I15:I16,I18:I41),0) -> 100 | J42: =SUM(J16:J41) -> 86.2
A44: ITEM | B44: 2. TRANSPORTES | L44: FONTE | M44: NOTAS
B45: Mobilização | C45: Equipamento | D45: Capacidade | E45: Saída | F45: Município de referência | H45: Viagens | I45: Frete unitário | J45: Custo Total
...

Sheet Perfil Master
B2: TABELA DE PREÇOS (2025)
B3: PERFIL MASTER
A7: Cliente: | B7: ='Perfuração Cardwell'!$D$7 -> SANEPAR
A8: Metragem Poço: | B8: ='Perfuração Cardwell'!$G$7 -> 870
A9: Deslocamento (Araraquara x Obra): | B9: ='Perfuração Cardwell'!J9 -> 337 | E9: =2200 -> 2200
A11: PARÂMETROS | B11: UNIDADE | C11: VALOR UNITÁRIO | D11: QUANTIDADE | E11: VALOR | F11: NOTAS
A12: Metragem Investigada | B12: m | C12: 18.5 | D12: =$B$8 -> 870 | E12: =$C$12*$D$12 -> 16095 | F12: Metragem do poço
A13: Deslocamento | B13: km | C13: 3.5 | D13: =$B$9*2 -> 674 | E13: =$C$13*$D$13 -> 2359 | F13: Deslocamento de Araraquara à obra (ida e volta)
A14: Relatório | B14: vb | C14: 650 | D14: 1 | E14: =$C$14*$D$14 -> 650 | F14: Sempre considerar o relatório, relativo a interpretação da Perfilagem Óptica
A15: Disponibilidade | B15: dia | C15: 1000 | D15: 1 | E15: =C15*D15 -> 1000
A16: Disponibilidade | B16: dia | C16: 2700 | D16: 1 | E16: =$C$16*$D$16 -> 2700 | F16: Adequar a quantidade de acordo com a integração do cliente (duração)
A17: Multi-Função | B17: m | C17: 18.5 | D17: =$B$8 -> 870 | E17: =$C$17*$D$17 -> 16095
A18: Cáliper | B18: m | C18: 16 | D18: =$B$8 -> 870 | E18: =$C$18*$D$18 -> 13920 | F18: Considerar quando houver reabertura do poço
A19: Sônico | B19: m | C19: 18.5 | D19: =$B$8 -> 870 | E19: =$C$19*$D$19 -> 16095
A20: FlowMeter | B20: m | C20: 18.5 | D20: =$B$8 -> 870 | E20: =$C$20*$D$20 -> 16095
A21: Interpretação dos Perfis | B21: m | C21: 8 | D21: =$B$8 -> 870 | E21: =$C$21*$D$21 -> 6960
A22: Inclinação com Tropari | B22: m | C22: 350 | D22: =$B$8/100 -> 8.7 | E22: =$C$22*$D$22 -> 3045 | F22: A cada 100m, considera-se uma quantidade
D23: PERFILAGEM ÓPTICA | E23: =SUM($E$12:$E$15)/$B$8 -> 23.108046
D24: PERFILAGEM GEOFÍSICA (CÁLIPER + INCLINAÇÃO) | E24: =SUM($E$18,$E$21,$E$22,$E$16,$E$13)/$B$8 -> 33.314943
D25: PERFILAGEM GEOFÍSICA (MULTI-FUNÇÃO + SÔNICO) | E25: =SUM($E$17,$E$19,$E$16,$E$13)/$B$8 -> 42.814943

Sheet Olho no Poço
B1: PLANILHA BASE PARCEIROS 2025
B3: OLHO NO POÇO PERFILAGEM ÓTICA E DIAGNÓSTICOS DE POÇOS ARTESIANOS LTDA
B4: Rua Dr Gualter Nunes, Nº 154
B5: Bairro: Chacara Junqueira, Tatuí-SP
B6: CEP 18.271-580
B8: NOME DO CLIENTE | C8: DH Perfurações | E8: DATA DO PEDIDO | F8: NÚMERO DO PEDIDO
B9: TELEFONE CLIENTE
B10: E-MAIL DO CLIENTE | E10: DATA DE INÍCIO ESPERADA | F10: DATA DE TÉRMINO ESPERADA
B11: LOCAL DE TRABALHO
B13: DESCRIÇÃO DO TRABALHO | D13: QUANTIDADE | E13: VALOR | F13: TOTAL
B14: KM rodado (considerando saida de Tatuí/ SP) | D14: 0 | E14: $2.35 | F14: $-
B15: Perfilagem Ótica até 400 m (Valor unitário por metro) | D15: 0 | E15: $13.00 | F15: $-
B16: Perfilagem Ótica de 400 a 600 m (Valor unitário por metro) | E16: $19.50
B17: Relatório simplificado c/ imagens e posições (até 300 metros) | E17: $600.00 | F17: $-
B18: Relatório simplificado c/ imagens e posições (300 à 400 metros) | E18: $900.00 | F18: $-
B19: Relatório simplificado c/ imagens e posições (400 à 600 metros) | E19: $1,200.00 | F19: $-
B20: Relatório detalhado c/ avaliação estrutural (até 400 metros) | D20: 0 | E20: $1,900.00 | F20: $-
B21: Relatório detalhado c/ avaliação estrutural (400 à 600 metros) | E21: $2,100.00 | F21: $-
B22: Diária (disponibilidade para dia trabalhado) | D22: 0 | E22: $990.00 | F22: $-
B23: Diária (deslocamento para viagem apena. Considerar quando deslocamento total superior a 500 km) | D23: 0 | E23: $1,250.00 | F23: $-
B24: Taxa de ART | D24: 0 | E24: $120.00 | F24: $-
B25: Perfil Construtivo | D25: 0 | E25: $400.00 | F25: $-
B26: Pernoite (Considerar quando deslocamento total superior a 500 km) | D26: 0 | E26: $350.00 | F26: $-
B27: Imprevistos e Operacional | F27: $-
E28: TOTAL MÃO DE OBRA | F28: $-

Sheet Resumo
C2: CUSTEIO PERFURAÇÃO
C3: RESUMO
C4: FATURAMENTO DH
A6: LEGENDA | D6: DADOS | G6: POÇO | K6: DESLOCAMENTOS | V6: PERFURAÇÃO | W6: SERVIÇOS
B7: Células a serem preenchidas, conforme projeto/internamente | C7: Cliente: | D7: ='Perfuração Cardwell'!D7 -> SANEPAR | F7: Prof. (m) | G7: ='Perfuração Cardwell'!G7 -> 870 | K7: Campinas(km) | L7: ='Perfuração Cardwell'!J7 -> 440 | N7: PREÇO METRO (R$) | S7: 0 - NÃO | T7: 1 - SIM | V7: =SUM('Perfuração Cardwell'!J155:J159)*Resumo!S8+'Perfuração Cardwell'!J163+SUM('Perfuração Cardwell'!J139:J140) -> 60404.4 | W7: =SUM(#REF!,$J$74)*Resumo!S9 -> #REF!
B8: Responsabilidades Contratante/Contratada | C8: Município: | D8: ='Perfuração Cardwell'!D8 -> Cornélio Procópio/PR | F8: N.E. (m) | G8: ='Perfuração Cardwell'!G8 -> 0 | K8: São Paulo (km) | L8: ='Perfuração Cardwell'!J8 -> 464 | N8: ='Perfuração Cardwell'!J219 -> 7310.0505 | Q8: FAT. DIRETO | S8: 0
A9: - | B9: Itens direcionados ao Faturamento Direto/Preço de venda dos materiais | C9: Endereço: | D9: ='Perfuração Cardwell'!D9 -> Rua dos Expedicionários S/N | F9: N.D. (m) | G9: ='Perfuração Cardwell'!G9 -> 280 | K9: Araraquara (km) | L9: ='Perfuração Cardwell'!J9 -> 337 | Q9: FAT. DIRETO SERV. + MATERIAIS | S9: 0
A10: - | B10: Preço de venda do poço | F10: Q (m³/h) | G10: ='Perfuração Cardwell'!G10 -> 300 | K10: Jundiaí (km) | L10: ='Perfuração Cardwell'!J10 -> 439
F11: S (m) | G11: ='Perfuração Cardwell'!G11 -> 0
A13: ITEM | B13: 1. RESUMO
A14: 1.1 | B14: Descrição | C14: Mark-Up | D14: Preço de Venda (R$) | E14: Desconto (%) | F14: Receita Líquida (R$) | G14: Custo Total (R$) | H14: Custo M.O (R$) | I14: Depreciação Equipamentos (R$) | J14: Risco (%) | K14: Risco (R$) | L14: Margem Operacional (%) | M14: Margem líquida (%) | N14: QTD | Q14: Venda Total (R$) | R14: Receita Líquida (R$) | S14: Custo Total (R$) | T14: Custo M.O (R$) | U14: Depreciação Equipamentos (R$)
A15: 1.3 | B15: Perfuração Cardwell | C15: 1.875 | D15: ='Perfuração Cardwell'!H215 -> 6359743.9 | E15: 0.165 | F15: ='Perfuração Cardwell'!H219 -> 6000418.4 | G15: ='Perfuração Cardwell'!H221 -> 4062111.9 | H15: ='Perfuração Cardwell'!J202 -> 724729.21 | I15: ='Perfuração Cardwell'!J205 -> 62580.462 | J15: 0.15 | K15: ='Perfuração Cardwell'!J210 -> 529840.68 | L15: ='Perfuração Cardwell'!G222 -> 0.32302856 | M15: ='Perfuração Cardwell'!H229 -> 0.17302856 | N15: 1 | Q15: =D15*N15 -> 6359743.9 | R15: =F15*N15 -> 6000418.4 | S15: =G15*N15 -> 4062111.9 | T15: =H15*N15 -> 724729.21 | U15: =I15*N15 -> 62580.462
P16: TOTAL | Q16: =SUM(Q15:Q15) -> 6359743.9 | R16: =SUM(R15:R15) -> 6000418.4 | S16: =SUM(S15:S15) -> 4062111.9 | T16: =SUM(T15:T15) -> 724729.21 | U16: =SUM(U15:U15) -> 62580.462
A17: RESULTADO GERAL
A18: 1 | B18: FATOR DE VENDA | M18: FAT. DIRETO | N18: TOTAL PROPOSTA
A19: 2 | B19: PREÇO DE VENDA | K19: =Q16 -> 6359743.9 | M19: ='Perfuração Cardwell'!I215 -> 0 | N19: =K19 -> 6359743.9
A20: 3 | B20: IMPOSTOS (PIS+COFINS) | K20: =$K19*J20 -> 0
A21: 4 | B21: IMPOSTOS (ISS) - Variável | K21: =$K19*J21 -> 0 | M21: Valor de referência | N21: 7620820
A22: 5 | B22: VENDA LÍQUIDA | K22: =R16 -> 6000418.4
A23: 6 | B23: COMISSÃO | K23: =$K19*J23 -> 0 | Q23: ISS Adotado | R23: 0.02
A24: 7 | B24: CUSTO TOTAL (IMPOSTOS + CUSTO OPERACIONAL + COMISSÃO) | K24: =S16+K23 -> 4062111.9 | Q24: BASE DE CÁLCULO REDUZIDA | R24: =K19-SUM('Perfuração Cardwell'!J140,'Perfuração Cardwell'!J139,'Perfuração Cardwell'!J155:J159,'Perfuração Cardwell'!J163) -> 5395862
A25: 8 | B25: LUCRO OPERACIONAL | J25: =K25/K22 -> 0.32302856 | K25: =K22-K24 -> 1938306.5 | Q25: TOTAL ISS REDUZIDO | R25: =R23*R24 -> 107917.24
A26: 9 | B26: ADMINISTRAÇÃO CENTRAL | J26: 0.15 | K26: =$K22*J26 -> 900062.76 | Q26: ECONOMIA TOTAL | R26: =K19*R23-R25 -> 19277.639
A27: 10 | B27: MARGEM BRUTA DE CONTRIBUIÇÃO | J27: =K27/K22 -> 0.17302856 | K27: =K25-K26 -> 1038243.7 | Q27: % SOBRE RECEITA LIQUIDA | R27: =R26/K19 -> 0.0030311973
A28: 11 | B28: IMPOSTOS (IRPJ) 25% | K28: =$K27*J28 -> 0 | Q28: LUCRO LÍQUIDO + ECONOMIA | R28: =K31+R26 -> 1057521.4
A29: 12 | B29: IMPOSTOS (CSLL) 9% | K29: =$K27*J29 -> 0 | Q29: % LUCRO LÍQUIDO | R29: =R28/K22 -> 0.17624127
A30: 13 | B30: CUSTO FINANCEIRO - BASE 1% ao mês | K30: =$K19*J30 -> 0
A31: 14 | B31: LUCRO LÍQUIDO | K31: =K27-SUM(K28:K30) -> 1038243.7
B32: RESULTADO | K32: =K31/K22 -> 0.17302856

Sheet Rascunho
C23: Solicitado a Núbia confirmar na prefeitura a aliquota para o código 7.02
