Workbook

Sheet Abril
A1: CONTROLE DE HORAS PARADAS - ABRIL
A3: Data | B3: Projeto | C3: Equipe | D3: Equipamento | E3: Horas Totais | F3: Horas Trabalhadas | G3: Horas Paradas | H3: Parada DH-GEL | I3: Parada SANEPAR | J3: Parada Chuva | K3: DTM | L3: Preparação de canteiro | M3: Parada Mecânica | N3: Outros Motivos | O3: Motivo / Justificativa | P3: Responsável | Q3: Nº RDO | R3: Observações
A4: 46113 | B4: Sanepar | D4: Terraplanagem Escavadeira | G4: =E4-F4 -> 0 | N4: =SUM(H4:M4) -> 0 | O4: Concluindo terraplanagem
A5: 46114 | G5: =E5-F5 -> 0 | N5: =SUM(H5:M5) -> 0
A6: 46115 | G6: =E6-F6 -> 0 | N6: =SUM(H6:M6) -> 0
A7: 46116 | G7: =E7-F7 -> 0 | N7: =SUM(H7:M7) -> 0
A8: 46117 | G8: =E8-F8 -> 0 | N8: =SUM(H8:M8) -> 0
A9: 46118 | G9: =E9-F9 -> 0 | N9: =SUM(H9:M9) -> 0
A10: 46119 | G10: =E10-F10 -> 0 | N10: =SUM(H10:M10) -> 0
A11: 46120 | G11: =E11-F11 -> 0 | N11: =SUM(H11:M11) -> 0
A12: 46121 | G12: =E12-F12 -> 0 | N12: =SUM(H12:M12) -> 0
A13: 46122 | G13: =E13-F13 -> 0 | N13: =SUM(H13:M13) -> 0
A14: 46123 | G14: =E14-F14 -> 0 | N14: =SUM(H14:M14) -> 0
A15: 46124 | G15: =E15-F15 -> 0 | N15: =SUM(H15:M15) -> 0
A16: 46125 | G16: =E16-F16 -> 0 | N16: =SUM(H16:M16) -> 0
... A22: 46131 | G22: =E22-F22 -> 0 | N22: =SUM(H22:M22) -> 0
A23: 46132 | B23: SANEPAR | C23: 1 TURNO | D23: CARDWELL | E23: 0.41666667 | F23: 0.41666667 | G23: =E23-F23 -> 0 | K23: 0.41666667 | N23: =SUM(H23:M23) -> 0.41666667 | O23: DTM (MOBILIZAÇÃO )
A24: 46133 | B24: SANEPAR | C24: 1 TURNO | D24: CARDWELL | E24: 0.39930556 | F24: 0.39930556 | G24: =E24-F24 -> 0 | K24: 0.16666667 | L24: 0.23263889 | N24: =SUM(H24:M24) -> 0.39930556 | O24: DTM (MOBILIZAÇÃO )/ fazendo base de concreto
A25: 46134 | B25: SANEPAR | C25: 1 TURNO | D25: CARDWELL | E25: 0.375 | F25: 0.375 | G25: =E25-F25 -> 0 | L25: 0.375 | N25: =SUM(H25:M25) -> 0.375 | O25: Fazendo base de concreto
A26: 46135 | B26: SANEPAR | C26: 1 TURNO | D26: CARDWELL | E26: 0.375 | F26: 0.375 | G26: =E26-F26 -> 0 | L26: 0.16666667 | N26: =SUM(H26:M26) -> 0.16666667 | O26: Terminando base de concreto/ Deslocamento | R26: 20,5 m³ de concreto
A27: 46136 | B27: SANEPAR | C27: 1 TURNO | D27: CARDWELL | G27: =E27-F27 -> 0 | N27: =SUM(H27:M27) -> 0
A28: 46137 | B28: SANEPAR | C28: 1 TURNO | D28: CARDWELL | G28: =E28-F28 -> 0 | N28: =SUM(H28:M28) -> 0
A29: 46138 | B29: SANEPAR | C29: 1 TURNO | D29: CARDWELL | G29: =E29-F29 -> 0 | N29: =SUM(H29:M29) -> 0
A30: 46139 | B30: SANEPAR | C30: 1 TURNO | D30: CARDWELL | E30: 0.45833333 | F30: 0.45833333 | G30: =E30-F30 -> 0 | K30: 0.45833333 | N30: =SUM(H30:M30) -> 0.45833333 | O30: DTM / CARREGANDO CARRETA COM EQUIPAMENTOS SONDA CARDWELL
A31: 46140 | B31: SANEPAR | C31: 1 TURNO | D31: CARDWELL | E31: 0.46527778 | F31: 0.46527778 | G31: =E31-F31 -> 0 | K31: 0.46527778 | N31: =SUM(H31:M31) -> 0.46527778 | O31: DTM / CARREGANDO CARRETA COM EQUIPAMENTOS SONDA CARDWELL
A32: 46141 | B32: SANEPAR | C32: 1 TURNO | D32: CARDWELL | E32: 0.47916667 | F32: 0.47916667 | G32: =E32-F32 -> 0 | K32: 0.47916667 | N32: =SUM(H32:M32) -> 0.47916667 | O32: DTM / CARREGANDO SONDA CARDWELL E MUNCK / INDO PARA SANEPAR
A33: 46142 | B33: SANEPAR | C33: 1 TURNO | D33: CARDWELL | E33: 0.47916667 | F33: 0.3125 | G33: =E33-F33 -> 0.16666667 | K33: 0.3125 | N33: =SUM(H33:M33) -> 0.3125 | O33: DESCARREGANDO CONTAINER / 4 HS AGUARDANDO SOLO SECAR P/ O CAMINHÃO ENTRAR NO CANTEIRO | R33: RETROESCAVADEIRA CHEGOU NO LOCAL
E35: TOTAL | F35: TOTAL | G35: TOTAL | H35: TOTAL | I35: TOTAL | J35: TOTAL | K35: TOTAL | L35: TOTAL | M35: TOTAL
E36: =SUM(E4:E33) -> 3.4479167 | F36: =SUM(F4:F33) -> 3.28125 | G36: =SUM(G4:G33) -> 0.16666667 | H36: =SUM(H4:H33) -> 0 | I36: =SUM(I4:I33) -> 0 | J36: =SUM(J4:J33) -> 0 | K36: =SUM(K4:K33) -> 2.2986111 | L36: =SUM(L4:L33) -> 0.77430556 | M36: =SUM(M4:M33) -> 0
A38: RESUMO AUTOMÁTICO DE HORAS
A40: Total Horas do Projeto | C40: =SUM(E4:E33) -> 3.4479167 | E40: =C40/11 -> 0.31344697 | F40: dias
A41: Total Horas Trabalhadas | C41: =SUM(F4:F33) -> 3.28125 | E41: =C41/11 -> 0.29829545 | F41: dias
A42: Total Horas Paradas | C42: =SUM(G4:G33) -> 0.16666667 | E42: =C42/11 -> 0.015151515 | F42: dias
A43: Total Horas DH-GEL Engenharia | C43: =SUM(H4:H33) -> 0 | E43: =C43/11 -> 0 | F43: dias
A44: Total Horas SANEPAR | C44: =SUM(I4:I33) -> 0 | E44: =C44/11 -> 0 | F44: dias
A45: Total Horas Chuva | C45: =SUM(J4:J33) -> 0 | E45: =C45/11 -> 0 | F45: dias
A46: Total Horas Mecânica | C46: =SUM(M4:M33) -> 0 | E46: =C46/11 -> 0 | F46: dias
A47: DTM | C47: =K36 -> 2.2986111 | E47: =C47/6 -> 0.38310185 | F47: dias
A48: Preparação de canteiro | C48: =L36 -> 0.77430556 | E48: =C48/11 -> 0.070391414 | F48: dias
A50: H x H no Projeto | C50: =SUM(F4:F33) -> 3.28125

Sheet Maio 
A1: CONTROLE DE HORAS PARADAS - MAIO
A3: Data | B3: Projeto | C3: Equipe | D3: Equipamento | E3: Horas Totais | F3: Horas Trabalhadas | G3: Horas Paradas | H3: Parada DH_GEL | I3: Parada SANEPAR | J3: Parada Chuva | K3: DTM | L3: Base de Concreto | M3: Aguardando Material | N3: Parada Mecânica | O3: Outros Motivos | P3: Motivo / Justificativa | Q3: Responsável | R3: Nº RDO | S3: Observações
A4: 46143 | B4: SANEPAR | C4: 1 TURNO | D4: CARDWELL | E4: 0.48611111 | F4: 0.48611111 | G4: =E4-F4 -> 0 | K4: 0.48611111 | O4: =SUM(H4:N4) -> 0.48611111 | P4: DESCARREGANDO E MONTANDO SONDA CARDWELL
A5: 46144 | B5: SANEPAR | C5: 1 TURNO | D5: CARDWELL | E5: 0.45833333 | F5: 0.45833333 | G5: =E5-F5 -> 0 | K5: 0.45833333 | O5: =SUM(H5:N5) -> 0.45833333 | P5: DESCARREGANDO E MONTANDO EQUIPAMENTOS/ CASINHA DA SONDA CARDWELL
A6: 46145 | B6: SANEPAR | C6: 1 TURNO | D6: CARDWELL | E6: 0.45833333 | F6: 0.45833333 | G6: =E6-F6 -> 0 | K6: 0.45833333 | O6: =SUM(H6:N6) -> 0.45833333 | P6: PATOLANDO SONDA/LEVANTANDO TORRE/MONTANDO PLATAFORMA DO TORRISTA/SUBINDO MASTRO/MONTANDO SUPORTES DOS BRAÇOS DA TORRE
A7: 46146 | B7: SANEPAR | D7: CARDWELL | G7: =E7-F7 -> 0 | O7: =SUM(H7:N7) -> 0
A8: 46147 | B8: SANEPAR | D8: CARDWELL | G8: =E8-F8 -> 0 | O8: =SUM(H8:N8) -> 0
A9: 46148 | B9: SANEPAR | D9: CARDWELL | G9: =E9-F9 -> 0 | O9: =SUM(H9:N9) -> 0
A10: 46149 | B10: SANEPAR | C10: 1 TURNO | D10: CARDWELL | E10: 0.45833333 | F10: 0.45833333 | G10: =E10-F10 -> 0 | K10: 0.45833333 | O10: =SUM(H10:N10) -> 0.45833333 | P10: POSICIONANDO BOMBA VULCAN/PREPARAÇÃO DE FLUIDOS/MONTANDO LINHA DE FLUIDO DA BOMBA E FALNGES DA BOMBA CENTRIFUGA
A11: 46150 | B11: SANEPAR | C11: 1 TURNO | D11: CARDWELL | E11: 0.43055556 | F11: 0.40277778 | G11: =E11-F11 -> 0.027777778 | J11: 0.027777778 | K11: 0.40277778 | O11: =SUM(H11:N11) -> 0.43055556 | P11: PARALIZADO POR MOTIVOS CLIMATICOS | S11: POSICIONANDO CAIXA DE FERRO/DESCARREGANDO RESERVATORIO E CONTAINER
A12: 46151 | B12: SANEPAR | C12: 1 TURNO | D12: CARDWELL | E12: 0.41666667 | F12: 0.097222222 | G12: =E12-F12 -> 0.31944444 | J12: 0.31944444 | K12: 0.097222222 | O12: =SUM(H12:N12) -> 0.41666667 | P12: PARALIZADO POR MOTIVOS CLIMATICOS | S12: DESCARREGANDO COMPRESSOR DH E RECEBENDO COMPRESSOR ALUGADO
A13: 46152 | B13: SANEPAR | C13: 1 TURNO | D13: CARDWELL | E13: 0.34722222 | F13: 0.16666667 | G13: =E13-F13 -> 0.18055556 | J13: 0.18055556 | K13: 0.16666667 | O13: =SUM(H13:N13) -> 0.34722222 | P13: PARALIZADO POR MOTIVOS CLIMATICOS | S13: cercando a obra/eletricista fazendo instalação e aterramento da sonda
A14: 46153 | B14: SANEPAR | C14: 1 TURNO | D14: CARDWELL | E14: 0.45833333 | F14: 0.45833333 | G14: =E14-F14 -> 0 | O14: =SUM(H14:N14) -> 0 | P14: cortando tubo de boca/montando martelo, kelly | S14: perfurando até 3m da bainha do kelly/ utilizou 400kg de cimento no tubo de boca
A15: 46154 | B15: SANEPAR | C15: 1 TURNO | D15: CARDWELL | E15: 0.42361111 | F15: 0.42361111 | G15: =E15-F15 -> 0 | O15: =SUM(H15:N15) -> 0 | S15: trocou martelo bits de 12", montou com martelo bits de 18" iniciou perfuração com martelo de 18" perfurando poço de 00 m a 3 metros para testar martelo/40 mil litros de água (4 viagens com caminhão pipa DH)
A16: 46155 | B16: SANEPAR | C16: 1 TURNO | D16: CARDWELL | E16: 0.47916667 | F16: 0.47916667 | G16: =E16-F16 -> 0 | O16: =SUM(H16:N16) -> 0 | S16: Perfurou de 3 a 31,80 metros/40 mil litros de água (4 viagens com caminhão pipa DH)
A17: 46156 | B17: SANEPAR | C17: 1 TURNO | D17: CARDWELL | E17: 0.46875 | F17: 0.46875 | G17: =E17-F17 -> 0 | O17: =SUM(H17:N17) -> 0 | S17: Perfurou de 31,80 metros a 64 metros/50 mil litros de água (5 viagens com caminhão pipa DH)
A18: 46157 | B18: SANEPAR | C18: 1 TURNO | D18: CARDWELL | E18: 0.46805556 | F18: 0.46805556 | G18: =E18-F18 -> 0 | O18: =SUM(H18:N18) -> 0 | S18: Perfurou de 64 a 95,5 metros/40 mil litros de água (4 viagens com caminhão pipa DH)
A19: 46158 | B19: SANEPAR | C19: 1 TURNO | D19: CARDWELL | E19: 0.45138889 | F19: 0.45138889 | G19: =E19-F19 -> 0 | O19: =SUM(H19:N19) -> 0 | S19: Perfurou de 95,50 a 117 metros/50 mil litros de água (5 viagens com caminhão pipa DH)
A20: 46159 | B20: SANEPAR | C20: 1 TURNO | D20: CARDWELL | E20: 0.44791667 | F20: 0.44791667 | G20: =E20-F20 -> 0 | O20: =SUM(H20:N20) -> 0 | S20: Perfurou de 117 a 147 metros/60 mil litros de Água (6 viagens com caminhão pipa DH)
A21: 46160 | B21: SANEPAR | C21: 1 TURNO | D21: CARDWELL | E21: 0.45833333 | F21: 0.45833333 | G21: =E21-F21 -> 0 | O21: =SUM(H21:N21) -> 0 | S21: Perfurou de 147 a 176,20 metros/80 mil litros de água (8 viagens com caminhão pipa DH)
A22: 46161 | B22: SANEPAR | C22: 1 TURNO | D22: CARDWELL | E22: 0.44444444 | F22: 0.35763889 | G22: =E22-F22 -> 0.086805556 | M22: 0.086805556 | O22: =SUM(I22:N22) -> 0.086805556 | P22: Aguardando caminhão pipa DH | S22: Perfurou de 176,20 a 197 metros/60 mil litros de água (6 viagens com caminhão pipa DH)
A23: 46162 | B23: SANEPAR | C23: 1 TURNO | D23: CARDWELL | E23: 0.45833333 | F23: 0.40277778 | G23: =E23-F23 -> 0.055555556 | M23: 0.055555556 | O23: =SUM(H23:N23) -> 0.055555556 | P23: Aguardando Diesel | S23: Perfurou de 197 a 211 metros
A24: 46163 | B24: SANEPAR | C24: 1 TURNO | D24: CARDWELL | E24: 0.41666667 | F24: 0.41666667 | G24: =E24-F24 -> 0 | O24: =SUM(H24:N24) -> 0 | S24: Parou perfuração para retirada do martelo e realizar a troca da broca para iniciar o repasse
A25: 46164 | B25: SANEPAR | C25: 1 TURNO | D25: CARDWELL | E25: 0.42708333 | F25: 0.42708333 | G25: =E25-F25 -> 0 | O25: =SUM(H25:N25) -> 0 | S25: Preparando operação para iniciar o repasse
A26: 46165 | B26: SANEPAR | C26: 1 TURNO | D26: CARDWELL | E26: 0.4375 | F26: 0.35416667 | G26: =E26-F26 -> 0.083333333 | N26: 0.083333333 | O26: =SUM(H26:N26) -> 0.083333333 | P26: Trocando cabo do guinchinho, Desmontando sensor do martin decker (balança veio quebrado, não tinha realizado manutenção depois que saiu da outra obra) | S26: Preparando canteiro, fazendo limpeza do tanque, fazendo os pés de apoio do tubo condutor
A27: 46166 | B27: SANEPAR | C27: 1 TURNO | D27: CARDWELL | E27: 0.47222222 | F27: 0.47222222 | G27: =E27-F27 -> 0 | O27: =SUM(H27:N27) -> 0 | S27: Descarregando munck/ ligação do tubo condutor para peneira/descendo hastes e lavando o poço
A28: 46167 | B28: SANEPAR | C28: 1 TURNO | D28: CARDWELL | E28: 0.44791667 | F28: 0.44791667 | G28: =E28-F28 -> 0 | O28: =SUM(H28:N28) -> 0 | S28: Descarregando bentonita, tirando coluna de hastes do poço/ batendo tanque de lama e montando coluna para reabrir a boca do poço
A29: 46168 | B29: SANEPAR | C29: 1 TURNO | D29: CARDWELL | E29: 0.43055556 | F29: 0.43055556 | G29: =E29-F29 -> 0 | O29: =SUM(H29:N29) -> 0 | S29: Repassando o poço de 3 a 11,52 metros/ descendo comando mais topou mais pra baixo(o que topou mais em baixo?)
A30: 46169 | B30: SANEPAR | C30: 1 TURNO | D30: CARDWELL | E30: 0.4375 | F30: 0.4375 | G30: =E30-F30 -> 0 | O30: =SUM(H30:N30) -> 0 | S30: Repassando o poço de 11,52 a 20 metros/ desmontando parte do martin deker e tirando parte da coluna
A31: 46170 | B31: SANEPAR | C31: 2 TURNO | D31: CARDWELL | E31: 1 | F31: 1 | G31: =E31-F31 -> 0 | O31: =SUM(H31:N31) -> 0 | S31: Repassando o poço até 34,08/ turno da noite repassou de 23 a 70,91
A32: 46171 | B32: SANEPAR | C32: 2 TURNO | D32: CARDWELL | E32: 1 | F32: 0.84722222 | G32: =E32-F32 -> 0.15277778 | H32: 0.069444444 | N32: 0.083333333 | O32: =SUM(H32:N32) -> 0.15277778 | P32: Trocando graxeta (conjunto grajeta do swivel) | S32: Repassando o poço até 120 metros
A33: 46172 | B33: SANEPAR | C33: 2 TURNO | D33: CARDWELL | E33: 1 | F33: 1 | G33: =E33-F33 -> 0 | O33: =SUM(H33:N33) -> 0 | S33: Repassando o poço até 213,30 metros
A34: 46173 | B34: SANEPAR | C34: 2 TURNO | D34: CARDWELL | E34: 1 | F34: 1 | G34: =E34-F34 -> 0 | O34: =SUM(H34:N34) -> 0 | S34: Perfurando até 238,80 metros
E36: TOTAL | F36: TOTAL | G36: TOTAL | H36: TOTAL | I36: TOTAL | J36: TOTAL | K36: TOTAL | L36: TOTAL | M36: TOTAL | N36: TOTAL
E37: =SUM(E4:E34) -> 14.683333 | F37: =SUM(F4:F34) -> 13.777083 | G37: =SUM(G4:G34) -> 0.90625 | H37: =SUM(H4:H34) -> 0.069444444 | I37: =SUM(I4:I34) -> 0 | J37: =SUM(J4:J34) -> 0.52777778 | K37: =SUM(K4:K34) -> 2.5277778 | L37: =SUM(L4:L34) -> 0 | ... N37: =SUM(N4:N34) -> 0.16666667
A40: RESUMO AUTOMÁTICO DE HORAS
A42: Total Horas do Projeto | C42: =SUM(E4:E33) -> 13.683333 | E42: =C42/24 -> 0.57013889 | F42: dias
A43: Total Horas Trabalhadas | C43: =SUM(F4:F33) -> 12.777083 | E43: =C43/24 -> 0.53237847 | F43: dias
A44: Total Horas Paradas | C44: =SUM(G4:G33) -> 0.90625 | E44: =C44/24 -> 0.037760417 | F44: dias
A45: Total Horas DH-GEL Engenharia | C45: =SUM(H4:H33) -> 0.069444444 | E45: =C45/24 -> 0.0028935185 | F45: dias
...

Sheet JUNHO
A1: CONTROLE DE HORAS PARADAS - MAIO
A3: Data | B3: Projeto | C3: Equipe | D3: Equipamento | E3: Horas Totais | F3: Horas Trabalhadas | G3: Horas Paradas | H3: Parada DH_GEL | I3: Parada Sanepar | J3: Parada Chuva | K3: DTM | L3: Base de Concreto | M3: Parada Mecânica | N3: Outros Motivos | O3: Motivo / Justificativa | P3: Responsável | Q3: Nº RDO | R3: Observações
A4: 46174 | B4: SANEPAR-PARANA | G4: =E4-F4 -> 0 | N4: =SUM(H4:M4) -> 0
A5: 46175 | G5: =E5-F5 -> 0 | N5: =SUM(H5:M5) -> 0
A6: 46176 | G6: =E6-F6 -> 0 | N6: =SUM(H6:M6) -> 0
A7: 46177 | G7: =E7-F7 -> 0 | N7: =SUM(H7:M7) -> 0
A8: 46178 | G8: =E8-F8 -> 0 | N8: =SUM(H8:M8) -> 0
A9: 46179 | G9: =E9-F9 -> 0 | N9: =SUM(H9:M9) -> 0
A10: 46180 | G10: =E10-F10 -> 0 | N10: =SUM(H10:M10) -> 0
A11: 46181 | G11: =E11-F11 -> 0 | N11: =SUM(H11:M11) -> 0
A12: 46182 | G12: =E12-F12 -> 0 | N12: =SUM(H12:M12) -> 0
A13: 46183 | G13: =E13-F13 -> 0 | N13: =SUM(H13:M13) -> 0
A14: 46184 | G14: =E14-F14 -> 0 | N14: =SUM(H14:M14) -> 0
A15: 46185 | G15: =E15-F15 -> 0 | N15: =SUM(H15:M15) -> 0
A16: 46186 | G16: =E16-F16 -> 0 | N16: =SUM(H16:M16) -> 0
... A33: 46203 | G33: =E33-F33 -> 0 | N33: =SUM(H33:M33) -> 0
E36: TOTAL | F36: TOTAL | G36: TOTAL | H36: TOTAL | I36: TOTAL | J36: TOTAL | M36: TOTAL
E37: =SUM(E4:E33) -> 0 | F37: =SUM(F4:F33) -> 0 | G37: =SUM(G4:G33) -> 0 | H37: =SUM(H4:H33) -> 0 | I37: =SUM(I4:I33) -> 0 | J37: =SUM(J4:J33) -> 0 | K37: =SUM(K4:K33) -> 0 | L37: =SUM(L4:L33) -> 0 | M37: =SUM(M4:M33) -> 0
A40: RESUMO AUTOMÁTICO DE HORAS
A42: Total Horas do Projeto | D42: =SUM(E4:E33) -> 0 | F42: =D42/11 -> 0 | G42: dias
A43: Total Horas Trabalhadas | D43: =SUM(F4:F33) -> 0 | F43: =D43/11 -> 0 | G43: dias
A44: Total Horas Paradas | D44: =SUM(G4:G33) -> 0 | F44: =D44/11 -> 0 | G44: dias
A45: Total Horas DH-GEL Engenharia | D45: =SUM(H4:H33) -> 0 | F45: =D45/11 -> 0 | G45: dias
A46: Total Horas MRV | D46: =SUM(I4:I33) -> 0 | F46: =D46/11 -> 0 | G46: dias
A47: Total Horas Chuva | D47: =SUM(J4:J33) -> 0 | F47: =D47/11 -> 0 | G47: dias
A48: Total Horas Mecânica | D48: =SUM(M4:M33) -> 0 | F48: =D48/11 -> 0 | G48: dias
A49: Total de Horas DTM | D49: =SUM(M5:M34) -> 0 | F49: =D49/11 -> 0 | G49: dias
A50: Total de Horas Base de concreto | D50: =SUM(M6:M35) -> 0 | F50: =D50/11 -> 0 | G50: dias
A53: H x H no Projeto | D53: =SUM(F4:F33) -> 0

Sheet JULHO
A1: CONTROLE DE HORAS PARADAS - MAIO
A3: Data | B3: Projeto | C3: Equipe | D3: Equipamento | E3: Horas Totais | F3: Horas Trabalhadas | G3: Horas Paradas | H3: Parada DH_GEL | I3: Parada Sanepar | J3: Parada Chuva | K3: Parada Mecânica | L3: Outros Motivos | M3: Motivo / Justificativa | N3: Responsável | O3: Nº RDO | P3: Centro de Custo | Q3: Observações
G4: =E4-F4 -> 0 | L4: =SUM(H4:K4) -> 0
G5: =E5-F5 -> 0 | L5: =SUM(H5:K5) -> 0
G6: =E6-F6 -> 0 | L6: =SUM(H6:K6) -> 0
G7: =E7-F7 -> 0 | L7: =SUM(H7:K7) -> 0
G8: =E8-F8 -> 0 | L8: =SUM(H8:K8) -> 0
G9: =E9-F9 -> 0 | L9: =SUM(H9:K9) -> 0
G10: =E10-F10 -> 0 | L10: =SUM(H10:K10) -> 0
G11: =E11-F11 -> 0 | L11: =SUM(H11:K11) -> 0
G12: =E12-F12 -> 0 | L12: =SUM(H12:K12) -> 0
G13: =E13-F13 -> 0 | L13: =SUM(H13:K13) -> 0
G14: =E14-F14 -> 0 | L14: =SUM(H14:K14) -> 0
G15: =E15-F15 -> 0 | L15: =SUM(H15:K15) -> 0
... G33: =E33-F33 -> 0 | L33: =SUM(H33:K33) -> 0
G34: =E34-F34 -> 0
E36: TOTAL | F36: TOTAL | G36: TOTAL | H36: TOTAL | I36: TOTAL | J36: TOTAL | K36: TOTAL
E37: =SUM(E4:E33) -> 0 | F37: =SUM(F4:F33) -> 0 | G37: =SUM(G4:G33) -> 0 | H37: =SUM(H4:H33) -> 0 | I37: =SUM(I4:I33) -> 0 | J37: =SUM(J4:J33) -> 0 | K37: =SUM(K4:K33) -> 0
A40: RESUMO AUTOMÁTICO DE HORAS
A42: Total Horas do Projeto | D42: =SUM(E4:E33) -> 0 | F42: =D42/11 -> 0 | G42: dias
A43: Total Horas Trabalhadas | D43: =SUM(F4:F33) -> 0 | F43: =D43/11 -> 0 | G43: dias
A44: Total Horas Paradas | D44: =SUM(G4:G33) -> 0 | F44: =D44/11 -> 0 | G44: dias
A45: Total Horas DH-GEL Engenharia | D45: =SUM(H4:H33) -> 0 | F45: =D45/11 -> 0 | G45: dias
A46: Total Horas Parc das Artes | D46: =SUM(I4:I33) -> 0 | F46: =D46/11 -> 0 | G46: dias
A47: Total Horas Chuva | D47: =SUM(J4:J33) -> 0 | F47: =D47/11 -> 0 | G47: dias
A48: Total Horas Mecânica | D48: =SUM(K4:K33) -> 0 | F48: =D48/11 -> 0 | G48: dias
A49: Total de Horas DTM
A50: Total de Horas Base de concreto
A53: H x H no Projeto | D53: =SUM(F4:F33) -> 0

Sheet EQUIPAMENTOS
A1: CONTROLE DE HORAS PARADAS - ABRIL
A3: Data | B3: Projeto | C3: Equipe | D3: Equipamento | E3: Horário de: | F3: Horário até: | G3: Horas Paradas | H3: Motivo / Justificativa | I3: Responsável | J3: Horimetro Compressor
G4: =Tabela_Abril10[[#This Row],[Horário até:]]-Tabela_Abril10[[#This Row],[Horário de:]] -> 0
G5: =Tabela_Abril10[[#This Row],[Horário até:]]-Tabela_Abril10[[#This Row],[Horário de:]] -> 0
G6: =Tabela_Abril10[[#This Row],[Horário até:]]-Tabela_Abril10[[#This Row],[Horário de:]] -> 0
G7: =Tabela_Abril10[[#This Row],[Horário até:]]-Tabela_Abril10[[#This Row],[Horário de:]] -> 0
G8: =Tabela_Abril10[[#This Row],[Horário até:]]-Tabela_Abril10[[#This Row],[Horário de:]] -> 0
G9: =Tabela_Abril10[[#This Row],[Horário até:]]-Tabela_Abril10[[#This Row],[Horário de:]] -> 0
G10: =Tabela_Abril10[[#This Row],[Horário até:]]-Tabela_Abril10[[#This Row],[Horário de:]] -> 0
G11: =Tabela_Abril10[[#This Row],[Horário até:]]-Tabela_Abril10[[#This Row],[Horário de:]] -> 0
G12: =Tabela_Abril10[[#This Row],[Horário até:]]-Tabela_Abril10[[#This Row],[Horário de:]] -> 0
G13: =Tabela_Abril10[[#This Row],[Horário até:]]-Tabela_Abril10[[#This Row],[Horário de:]] -> 0
G14: =Tabela_Abril10[[#This Row],[Horário até:]]-Tabela_Abril10[[#This Row],[Horário de:]] -> 0
G15: =Tabela_Abril10[[#This Row],[Horário até:]]-Tabela_Abril10[[#This Row],[Horário de:]] -> 0
... G59: =Tabela_Abril10[[#This Row],[Horário até:]]-Tabela_Abril10[[#This Row],[Horário de:]] -> 0
G61: =SUM(G4:G59) -> 0
A63: RESUMO AUTOMÁTICO DE HORAS
A67: Total - Manutenção | B67: =SUM(G4:G59) -> 0
A68: Dias | B68: =B67/24 -> 0

Sheet PERFURAÇÃO
A1: CONTROLE DE PERFURAÇÃO
A3: Data | B3: Ferramenta | C3: De: | D3: Até: | E3: Quantidade Metros | F3: Viscosidade | G3: PH | H3: Tipo | I3: De | J3: Até | K3: Quantidade M Reaberto | L3: Horário Inicio | M3: Horário Término | N3: Tempo Perfuração | O3: Tempo Reabertura | P3: Tempo de Repasse | Q3: Diesel S10 | R3: Diesel S500 | S3: Observação
A4: 46154 | B4: Ø 18" - martelo | C4: 0 | D4: 3 | E4: =Tabela_Fevereiro88[[#This Row],[Até:]]-Tabela_Fevereiro88[[#This Row],[De:]] -> 3 | H4: Perfuração | K4: =Tabela_Fevereiro88[[#This Row],[Até]]-Tabela_Fevereiro88[[#This Row],[De]] -> 0 | L4: 0.72916667 | M4: 0.75694444 | N4: =Tabela_Fevereiro88[[#This Row],[Horário Término]]-Tabela_Fevereiro88[[#This Row],[Horário Inicio]] -> 0.027777778 | Q4: 332 | R4: 429
A5: 46155 | B5: Ø 18" - martelo | C5: 3 | D5: 5 | E5: =Tabela_Fevereiro88[[#This Row],[Até:]]-Tabela_Fevereiro88[[#This Row],[De:]] -> 2 | H5: Perfuração | K5: =Tabela_Fevereiro88[[#This Row],[Até]]-Tabela_Fevereiro88[[#This Row],[De]] -> 0 | L5: 0.40972222 | M5: 0.41666667 | N5: =Tabela_Fevereiro88[[#This Row],[Horário Término]]-Tabela_Fevereiro88[[#This Row],[Horário Inicio]] -> 0.0069444444 | Q5: 441 | R5: 542
B6: Ø 18" - martelo | C6: 5 | D6: 6 | E6: =Tabela_Fevereiro88[[#This Row],[Até:]]-Tabela_Fevereiro88[[#This Row],[De:]] -> 1 | H6: Perfuração | K6: =Tabela_Fevereiro88[[#This Row],[Até]]-Tabela_Fevereiro88[[#This Row],[De]] -> 0 | L6: 0.41666667 | M6: 0.42361111 | N6: =Tabela_Fevereiro88[[#This Row],[Horário Término]]-Tabela_Fevereiro88[[#This Row],[Horário Inicio]] -> 0.0069444444
B7: Ø 18" - martelo | C7: 6 | D7: 10 | E7: =Tabela_Fevereiro88[[#This Row],[Até:]]-Tabela_Fevereiro88[[#This Row],[De:]] -> 4 | H7: Perfuração | K7: =Tabela_Fevereiro88[[#This Row],[Até]]-Tabela_Fevereiro88[[#This Row],[De]] -> 0 | L7: 0.42361111 | M7: 0.4375 | N7: =Tabela_Fevereiro88[[#This Row],[Horário Término]]-Tabela_Fevereiro88[[#This Row],[Horário Inicio]] -> 0.013888889
B8: Ø 18" - martelo | C8: 10 | D8: 11 | E8: =Tabela_Fevereiro88[[#This Row],[Até:]]-Tabela_Fevereiro88[[#This Row],[De:]] -> 1 | H8: Perfuração | K8: =Tabela_Fevereiro88[[#This Row],[Até]]-Tabela_Fevereiro88[[#This Row],[De]] -> 0 | L8: 0.4375 | M8: 0.44444444 | N8: =Tabela_Fevereiro88[[#This Row],[Horário Término]]-Tabela_Fevereiro88[[#This Row],[Horário Inicio]] -> 0.0069444444
B9: Ø 18" - martelo | C9: 11 | D9: 12 | E9: =Tabela_Fevereiro88[[#This Row],[Até:]]-Tabela_Fevereiro88[[#This Row],[De:]] -> 1 | H9: Perfuração | K9: =Tabela_Fevereiro88[[#This Row],[Até]]-Tabela_Fevereiro88[[#This Row],[De]] -> 0 | L9: 0.44444444 | M9: 0.45138889 | N9: =Tabela_Fevereiro88[[#This Row],[Horário Término]]-Tabela_Fevereiro88[[#This Row],[Horário Inicio]] -> 0.0069444444
B10: Ø 18" - martelo | C10: 12 | D10: 13 | E10: =Tabela_Fevereiro88[[#This Row],[Até:]]-Tabela_Fevereiro88[[#This Row],[De:]] -> 1 | H10: Perfuração | K10: =Tabela_Fevereiro88[[#This Row],[Até]]-Tabela_Fevereiro88[[#This Row],[De]] -> 0 | L10: 0.45138889 | M10: 0.45833333 | N10: =Tabela_Fevereiro88[[#This Row],[Horário Término]]-Tabela_Fevereiro88[[#This Row],[Horário Inicio]] -> 0.0069444444
B11: Ø 18" - martelo | C11: 13 | D11: 17 | E11: =Tabela_Fevereiro88[[#This Row],[Até:]]-Tabela_Fevereiro88[[#This Row],[De:]] -> 4 | H11: Perfuração | K11: =Tabela_Fevereiro88[[#This Row],[Até]]-Tabela_Fevereiro88[[#This Row],[De]] -> 0 | L11: 0.53472222 | M11: 0.56944444 | N11: =Tabela_Fevereiro88[[#This Row],[Horário Término]]-Tabela_Fevereiro88[[#This Row],[Horário Inicio]] -> 0.034722222
B12: Ø 18" - martelo | C12: 17 | D12: 18 | E12: =Tabela_Fevereiro88[[#This Row],[Até:]]-Tabela_Fevereiro88[[#This Row],[De:]] -> 1 | H12: Perfuração | K12: =Tabela_Fevereiro88[[#This Row],[Até]]-Tabela_Fevereiro88[[#This Row],[De]] -> 0 | L12: 0.56944444 | M12: 0.58333333 | N12: =Tabela_Fevereiro88[[#This Row],[Horário Término]]-Tabela_Fevereiro88[[#This Row],[Horário Inicio]] -> 0.013888889
B13: Ø 18" - martelo | C13: 18 | D13: 21 | E13: =Tabela_Fevereiro88[[#This Row],[Até:]]-Tabela_Fevereiro88[[#This Row],[De:]] -> 3 | H13: Perfuração | K13: =Tabela_Fevereiro88[[#This Row],[Até]]-Tabela_Fevereiro88[[#This Row],[De]] -> 0 | L13: 0.58333333 | M13: 0.59375 | N13: =Tabela_Fevereiro88[[#This Row],[Horário Término]]-Tabela_Fevereiro88[[#This Row],[Horário Inicio]] -> 0.010416667
B14: Ø 18" - martelo | C14: 21 | D14: 22 | E14: =Tabela_Fevereiro88[[#This Row],[Até:]]-Tabela_Fevereiro88[[#This Row],[De:]] -> 1 | H14: Perfuração | K14: =Tabela_Fevereiro88[[#This Row],[Até]]-Tabela_Fevereiro88[[#This Row],[De]] -> 0 | L14: 0.59375 | M14: 0.60416667 | N14: =Tabela_Fevereiro88[[#This Row],[Horário Término]]-Tabela_Fevereiro88[[#This Row],[Horário Inicio]] -> 0.010416667
B15: Ø 18" - martelo | C15: 22 | D15: 23 | E15: =Tabela_Fevereiro88[[#This Row],[Até:]]-Tabela_Fevereiro88[[#This Row],[De:]] -> 1 | H15: Perfuração | K15: =Tabela_Fevereiro88[[#This Row],[Até]]-Tabela_Fevereiro88[[#This Row],[De]] -> 0 | L15: 0.65277778 | M15: 0.65972222 | N15: =Tabela_Fevereiro88[[#This Row],[Horário Término]]-Tabela_Fevereiro88[[#This Row],[Horário Inicio]] -> 0.0069444444
B16: Ø 18" - martelo | C16: 23 | D16: 25 | E16: =Tabela_Fevereiro88[[#This Row],[Até:]]-Tabela_Fevereiro88[[#This Row],[De:]] -> 2 | H16: Perfuração | K16: =Tabela_Fevereiro88[[#This Row],[Até]]-Tabela_Fevereiro88[[#This Row],[De]] -> 0 | L16: 0.67361111 | M16: 0.69097222 | N16: =Tabela_Fevereiro88[[#This Row],[Horário Término]]-Tabela_Fevereiro88[[#This Row],[Horário Inicio]] -> 0.017361111
B17: Ø 18" - martelo | C17: 25 | D17: 26 | E17: =Tabela_Fevereiro88[[#This Row],[Até:]]-Tabela_Fevereiro88[[#This Row],[De:]] -> 1 | H17: Perfuração | K17: =Tabela_Fevereiro88[[#This Row],[Até]]-Tabela_Fevereiro88[[#This Row],[De]] -> 0 | L17: 0.69097222 | M17: 0.69444444 | N17: =Tabela_Fevereiro88[[#This Row],[Horário Término]]-Tabela_Fevereiro88[[#This Row],[Horário Inicio]] -> 0.0034722222
... B19: Ø 18" - martelo | C19: 27 | D19: 31.8 | E19: =Tabela_Fevereiro88[[#This Row],[Até:]]-Tabela_Fevereiro88[[#This Row],[De:]] -> 4.8 | H19: Perfuração | K19: =Tabela_Fevereiro88[[#This Row],[Até]]-Tabela_Fevereiro88[[#This Row],[De]] -> 0 | L19: 0.70833333 | M19: 0.75 | N19: =Tabela_Fevereiro88[[#This Row],[Horário Término]]-Tabela_Fevereiro88[[#This Row],[Horário Inicio]] -> 0.041666667
A20: 46156 | B20: Ø 18" - martelo | C20: 31.8 | D20: 40.2 | E20: =Tabela_Fevereiro88[[#This Row],[Até:]]-Tabela_Fevereiro88[[#This Row],[De:]] -> 8.4 | H20: Perfuração | K20: =Tabela_Fevereiro88[[#This Row],[Até]]-Tabela_Fevereiro88[[#This Row],[De]] -> 0 | L20: 0.33333333 | M20: 0.40277778 | N20: =Tabela_Fevereiro88[[#This Row],[Horário Término]]-Tabela_Fevereiro88[[#This Row],[Horário Inicio]] -> 0.069444444 | Q20: 491 | R20: 148 | S20: 633 litros de diesel(qual diesel?)
B21: Ø 18" - martelo | C21: 40.2 | D21: 41.2 | E21: =Tabela_Fevereiro88[[#This Row],[Até:]]-Tabela_Fevereiro88[[#This Row],[De:]] -> 1 | H21: Perfuração | K21: =Tabela_Fevereiro88[[#This Row],[Até]]-Tabela_Fevereiro88[[#This Row],[De]] -> 0 | L21: 0.43055556 | M21: 0.4375 | N21: =Tabela_Fevereiro88[[#This Row],[Horário Término]]-Tabela_Fevereiro88[[#This Row],[Horário Inicio]] -> 0.0069444444
B22: Ø 18" - martelo | C22: 41.2 | D22: 44 | E22: =Tabela_Fevereiro88[[#This Row],[Até:]]-Tabela_Fevereiro88[[#This Row],[De:]] -> 2.8 | H22: Perfuração | K22: =Tabela_Fevereiro88[[#This Row],[Até]]-Tabela_Fevereiro88[[#This Row],[De]] -> 0 | L22: 0.46527778 | M22: 0.48611111 | N22: =Tabela_Fevereiro88[[#This Row],[Horário Término]]-Tabela_Fevereiro88[[#This Row],[Horário Inicio]] -> 0.020833333
B23: Ø 18" - martelo | C23: 44 | D23: 45 | E23: =Tabela_Fevereiro88[[#This Row],[Até:]]-Tabela_Fevereiro88[[#This Row],[De:]] -> 1 | H23: Perfuração | K23: =Tabela_Fevereiro88[[#This Row],[Até]]-Tabela_Fevereiro88[[#This Row],[De]] -> 0 | L23: 0.48611111 | M23: 0.50347222 | N23: =Tabela_Fevereiro88[[#This Row],[Horário Término]]-Tabela_Fevereiro88[[#This Row],[Horário Inicio]] -> 0.017361111
B24: Ø 18" - martelo | C24: 45 | D24: 49 | E24: =Tabela_Fevereiro88[[#This Row],[Até:]]-Tabela_Fevereiro88[[#This Row],[De:]] -> 4 | H24: Perfuração | K24: =Tabela_Fevereiro88[[#This Row],[Até]]-Tabela_Fevereiro88[[#This Row],[De]] -> 0 | L24: 0.50347222 | M24: 0.54166667 | N24: =Tabela_Fevereiro88[[#This Row],[Horário Término]]-Tabela_Fevereiro88[[#This Row],[Horário Inicio]] -> 0.038194444
B25: Ø 18" - martelo | C25: 49 | D25: 51.31 | E25: =Tabela_Fevereiro88[[#This Row],[Até:]]-Tabela_Fevereiro88[[#This Row],[De:]] -> 2.31 | H25: Perfuração | K25: =Tabela_Fevereiro88[[#This Row],[Até]]-Tabela_Fevereiro88[[#This Row],[De]] -> 0 | L25: 0.54166667 | M25: 0.56944444 | N25: =Tabela_Fevereiro88[[#This Row],[Horário Término]]-Tabela_Fevereiro88[[#This Row],[Horário Inicio]] -> 0.027777778
B26: Ø 18" - martelo | C26: 51.31 | D26: 59 | E26: =Tabela_Fevereiro88[[#This Row],[Até:]]-Tabela_Fevereiro88[[#This Row],[De:]] -> 7.69 | H26: Perfuração | K26: =Tabela_Fevereiro88[[#This Row],[Até]]-Tabela_Fevereiro88[[#This Row],[De]] -> 0 | L26: 0.59722222 | M26: 0.67361111 | N26: =Tabela_Fevereiro88[[#This Row],[Horário Término]]-Tabela_Fevereiro88[[#This Row],[Horário Inicio]] -> 0.076388889
B27: Ø 18" - martelo | C27: 59 | D27: 60 | E27: =Tabela_Fevereiro88[[#This Row],[Até:]]-Tabela_Fevereiro88[[#This Row],[De:]] -> 1 | H27: Perfuração | K27: =Tabela_Fevereiro88[[#This Row],[Até]]-Tabela_Fevereiro88[[#This Row],[De]] -> 0 | L27: 0.67361111 | M27: 0.67708333 | N27: =Tabela_Fevereiro88[[#This Row],[Horário Término]]-Tabela_Fevereiro88[[#This Row],[Horário Inicio]] -> 0.0034722222
B28: Ø 18" - martelo | C28: 60 | D28: 60.8 | E28: =Tabela_Fevereiro88[[#This Row],[Até:]]-Tabela_Fevereiro88[[#This Row],[De:]] -> 0.8 | H28: Perfuração | K28: =Tabela_Fevereiro88[[#This Row],[Até]]-Tabela_Fevereiro88[[#This Row],[De]] -> 0 | L28: 0.67708333 | M28: 0.68055556 | N28: =Tabela_Fevereiro88[[#This Row],[Horário Término]]-Tabela_Fevereiro88[[#This Row],[Horário Inicio]] -> 0.0034722222
B29: Ø 18" - martelo | C29: 60.8 | D29: 64 | E29: =Tabela_Fevereiro88[[#This Row],[Até:]]-Tabela_Fevereiro88[[#This Row],[De:]] -> 3.2 | H29: Perfuração | K29: =Tabela_Fevereiro88[[#This Row],[Até]]-Tabela_Fevereiro88[[#This Row],[De]] -> 0 | L29: 0.70138889 | M29: 0.73263889 | N29: =Tabela_Fevereiro88[[#This Row],[Horário Término]]-Tabela_Fevereiro88[[#This Row],[Horário Inicio]] -> 0.03125
A30: 46157 | B30: Ø 18" - martelo | C30: 64 | D30: 70 | E30: =Tabela_Fevereiro88[[#This Row],[Até:]]-Tabela_Fevereiro88[[#This Row],[De:]] -> 6 | H30: Perfuração | K30: =Tabela_Fevereiro88[[#This Row],[Até]]-Tabela_Fevereiro88[[#This Row],[De]] -> 0 | L30: 0.31597222 | M30: 0.36111111 | N30: =Tabela_Fevereiro88[[#This Row],[Horário Término]]-Tabela_Fevereiro88[[#This Row],[Horário Inicio]] -> 0.045138889 | Q30: 774 | R30: 1168
B31: Ø 18" - martelo | C31: 70 | D31: 70.21 | E31: =Tabela_Fevereiro88[[#This Row],[Até:]]-Tabela_Fevereiro88[[#This Row],[De:]] -> 0.21 | H31: Perfuração | K31: =Tabela_Fevereiro88[[#This Row],[Até]]-Tabela_Fevereiro88[[#This Row],[De]] -> 0 | L31: 0.36111111 | M31: 0.36458333 | N31: =Tabela_Fevereiro88[[#This Row],[Horário Término]]-Tabela_Fevereiro88[[#This Row],[Horário Inicio]] -> 0.0034722222
B32: Ø 18" - martelo | C32: 70.21 | D32: 79.81 | E32: =Tabela_Fevereiro88[[#This Row],[Até:]]-Tabela_Fevereiro88[[#This Row],[De:]] -> 9.6 | H32: Perfuração | K32: =Tabela_Fevereiro88[[#This Row],[Até]]-Tabela_Fevereiro88[[#This Row],[De]] -> 0 | L32: 0.39236111 | M32: 0.46875 | N32: =Tabela_Fevereiro88[[#This Row],[Horário Término]]-Tabela_Fevereiro88[[#This Row],[Horário Inicio]] -> 0.076388889
B33: Ø 18" - martelo | C33: 79.81 | D33: 83 | E33: =Tabela_Fevereiro88[[#This Row],[Até:]]-Tabela_Fevereiro88[[#This Row],[De:]] -> 3.19 | H33: Perfuração | K33: =Tabela_Fevereiro88[[#This Row],[Até]]-Tabela_Fevereiro88[[#This Row],[De]] -> 0 | L33: 0.49652778 | M33: 0.55208333 | N33: =Tabela_Fevereiro88[[#This Row],[Horário Término]]-Tabela_Fevereiro88[[#This Row],[Horário Inicio]] -> 0.055555556
B34: Ø 18" - martelo | C34: 83 | D34: 86 | E34: =Tabela_Fevereiro88[[#This Row],[Até:]]-Tabela_Fevereiro88[[#This Row],[De:]] -> 3 | H34: Perfuração | K34: =Tabela_Fevereiro88[[#This Row],[Até]]-Tabela_Fevereiro88[[#This Row],[De]] -> 0 | L34: 0.58333333 | M34: 0.61458333 | N34: =Tabela_Fevereiro88[[#This Row],[Horário Término]]-Tabela_Fevereiro88[[#This Row],[Horário Inicio]] -> 0.03125
B35: Ø 18" - martelo | C35: 86 | D35: 89.48 | E35: =Tabela_Fevereiro88[[#This Row],[Até:]]-Tabela_Fevereiro88[[#This Row],[De:]] -> 3.48 | H35: Perfuração | K35: =Tabela_Fevereiro88[[#This Row],[Até]]-Tabela_Fevereiro88[[#This Row],[De]] -> 0 | L35: 0.61458333 | M35: 0.65277778 | N35: =Tabela_Fevereiro88[[#This Row],[Horário Término]]-Tabela_Fevereiro88[[#This Row],[Horário Inicio]] -> 0.038194444
B36: Ø 18" - martelo | C36: 89.48 | D36: 92 | E36: =Tabela_Fevereiro88[[#This Row],[Até:]]-Tabela_Fevereiro88[[#This Row],[De:]] -> 2.52 | H36: Perfuração | K36: =Tabela_Fevereiro88[[#This Row],[Até]]-Tabela_Fevereiro88[[#This Row],[De]] -> 0 | L36: 0.67361111 | M36: 0.69791667 | N36: =Tabela_Fevereiro88[[#This Row],[Horário Término]]-Tabela_Fevereiro88[[#This Row],[Horário Inicio]] -> 0.024305556
B37: Ø 18" - martelo | C37: 92 | D37: 95.5 | E37: =Tabela_Fevereiro88[[#This Row],[Até:]]-Tabela_Fevereiro88[[#This Row],[De:]] -> 3.5 | H37: Perfuração | K37: =Tabela_Fevereiro88[[#This Row],[Até]]-Tabela_Fevereiro88[[#This Row],[De]] -> 0 | L37: 0.69791667 | M37: 0.73611111 | N37: =Tabela_Fevereiro88[[#This Row],[Horário Término]]-Tabela_Fevereiro88[[#This Row],[Horário Inicio]] -> 0.038194444
A38: 46158 | B38: Ø 18" - martelo | C38: 95.5 | D38: 98.8 | E38: =Tabela_Fevereiro88[[#This Row],[Até:]]-Tabela_Fevereiro88[[#This Row],[De:]] -> 3.3 | H38: Perfuração | K38: =Tabela_Fevereiro88[[#This Row],[Até]]-Tabela_Fevereiro88[[#This Row],[De]] -> 0 | L38: 0.3125 | M38: 0.375 | N38: =Tabela_Fevereiro88[[#This Row],[Horário Término]]-Tabela_Fevereiro88[[#This Row],[Horário Inicio]] -> 0.0625 | Q38: 424 | R38: 672
B39: Ø 18" - martelo | C39: 98.8 | D39: 99.83 | E39: =Tabela_Fevereiro88[[#This Row],[Até:]]-Tabela_Fevereiro88[[#This Row],[De:]] -> 1.03 | H39: Perfuração | K39: =Tabela_Fevereiro88[[#This Row],[Até]]-Tabela_Fevereiro88[[#This Row],[De]] -> 0 | L39: 0.4375 | M39: 0.45486111 | N39: =Tabela_Fevereiro88[[#This Row],[Horário Término]]-Tabela_Fevereiro88[[#This Row],[Horário Inicio]] -> 0.017361111
B40: Ø 18" - martelo | C40: 99.83 | D40: 102 | E40: =Tabela_Fevereiro88[[#This Row],[Até:]]-Tabela_Fevereiro88[[#This Row],[De:]] -> 2.17 | H40: Perfuração | K40: =Tabela_Fevereiro88[[#This Row],[Até]]-Tabela_Fevereiro88[[#This Row],[De]] -> 0 | L40: 0.47222222 | M40: 0.49305556 | N40: =Tabela_Fevereiro88[[#This Row],[Horário Término]]-Tabela_Fevereiro88[[#This Row],[Horário Inicio]] -> 0.020833333
B41: Ø 18" - martelo | C41: 102 | D41: 106 | E41: =Tabela_Fevereiro88[[#This Row],[Até:]]-Tabela_Fevereiro88[[#This Row],[De:]] -> 4 | H41: Perfuração | K41: =Tabela_Fevereiro88[[#This Row],[Até]]-Tabela_Fevereiro88[[#This Row],[De]] -> 0 | L41: 0.53472222 | M41: 0.57291667 | N41: =Tabela_Fevereiro88[[#This Row],[Horário Término]]-Tabela_Fevereiro88[[#This Row],[Horário Inicio]] -> 0.038194444
B42: Ø 18" - martelo | C42: 106 | D42: 108.53 | E42: =Tabela_Fevereiro88[[#This Row],[Até:]]-Tabela_Fevereiro88[[#This Row],[De:]] -> 2.53 | H42: Perfuração | K42: =Tabela_Fevereiro88[[#This Row],[Até]]-Tabela_Fevereiro88[[#This Row],[De]] -> 0 | L42: 0.62152778 | M42: 0.63888889 | N42: =Tabela_Fevereiro88[[#This Row],[Horário Término]]-Tabela_Fevereiro88[[#This Row],[Horário Inicio]] -> 0.017361111
...

Sheet QUÍMICOS 
A1: CONTROLE DE QUIMICOS | M1: DASHBOARD - CONSUMO DE QUIMICOS
A3: Data | B3: CMC | C3: Goma Xantana | D3: Barilha | E3: Soda Caústica | F3: Hexa T | G3: Bentonita | H3: Hipoclorito de Sódio (lts) | I3: Óleo de Martelo | J3: Sabão de Martelo | K3: Motivo / Justificativa
A7: 46167 | G7: 1250
A8: 46168 | D8: 25 | G8: 1000
A10: 46172 | E10: 3 | G10: 125
G11: 750
A67: Quimicos | B67: CMC | C67: Goma X | D67: Barrilha | E67: Soda Caústica | F67: Hexa T | G67: Bentonita
A68: Planejado | B68: 1471.9 | C68: 0 | D68: 110 | E68: 0 | F68: 726.48 | G68: 32000 | H68: 330
A69: Realizado | B69: =SUM(B6:B65) -> 0 | C69: =SUM(C6:C66) -> 0 | D69: =SUM(D6:D66) -> 25 | E69: =SUM(E4:E65) -> 3 | G69: =SUM(G6:G65) -> 3125 | H69: =SUM(H6:H65) -> 0
A70: Imprevisto | B70: =B69-B68 -> -1471.9 | C70: =C69-C68 -> 0 | D70: =D69-D68 -> -85 | E70: =E69-E68 -> 3 | F70: =F69-F68 -> -726.48 | G70: =G69-G68 -> -28875 | H70: =H69-H68 -> -330
A71: Porcentagem | B71: =B69/B68 -> 0 | C71: =C69/C68 -> #DIV/0! | D71: =D69/D68 -> 0.22727273 | E71: =E69/E68 -> #DIV/0! | F71: =F69/F68 -> 0 | G71: =G69/G68 -> 0.09765625 | H71: =H69/H68 -> 0
A72: Status | B72: =IF(B69>B68,"ESTOURADO",IF(B70>=0.7,"ALERTA","OK")) -> OK | C72: =IF(C69>C68,"ESTOURADO",IF(C70>=0.7,"ALERTA","OK")) -> OK | D72: =IF(D69>D68,"ESTOURADO",IF(D70>=0.7,"ALERTA","OK")) -> OK | E72: =IF(E69>E68,"ESTOURADO",IF(E70>=0.7,"ALERTA","OK")) -> ESTOURADO | F72: =IF(F69>F68,"ESTOURADO",IF(F70>=0.7,"ALERTA","OK")) -> OK | G72: =IF(G69>G68,"ESTOURADO",IF(G70>=0.7,"ALERTA","OK")) -> OK | H72: =IF(H69>H68,"ESTOURADO",IF(H70>=0.7,"ALERTA","OK")) -> OK
A76: Soma da barrilha= soda caústica + barrilha
A77: *FAZER TESTE DE PH E DUREZA DA ÁGUA ANTES DE PLANEJAR A QUANTIDADE DE QUÍMICOS, PARA TER UMA ESTIMATIVA MAIS ACERTIVA!
A80: Goma Xantana não foi prevista no custeio do comercial para orçamento e foi acrescentado pelo Geologo no mapa de suprimentos 300 kg

Sheet EQUIPAMENTOS LOCADOS
A1: CONTROLE DE HORAS TRABALHADAS X PARADAS
A3: Data | B3: Projeto | C3: Fornecedor | D3: Equipamento | E3: Previsto | F3: Realizado | G3: Dias imprevisto | H3: Porcentagem % | I3: Status | J3: Parada DH_GEL | K3: Parada SANEPAR | L3: Parada Chuva | M3: Outros Motivos | N3: Motivo / Justificativa | O3: Horario Inicial | P3: Horario Final | Q3: Total Horas dia
A5: 46139 | B5: SANEPAR | C5: DONATO | D5: MUNCK | F5: 1
A6: 46140 | B6: SANEPAR | C6: DONATO | D6: MUNCK | F6: 1
A8: 46143 | D8: RETROESCAVADEIRA | F8: 1
E34: TOTAL DIAS PREVISTO | F34: TOTAL DIAS REALIZADOS | G34: TOTAL | H34: % | I34: STATUS | Q34: TOTAL
E35: =E4 -> 0 | F35: =SUM(F4:F23) -> 3 | G35: =Tabela_Fevereiro7[[#This Row],[Realizado]]-Tabela_Fevereiro7[[#This Row],[Previsto]] -> 3 | H35: =Tabela_Fevereiro7[[#This Row],[Realizado]]/Tabela_Fevereiro7[[#This Row],[Previsto]] -> #DIV/0! | I35: =IF(F35>E35,"ESTOURADO",IF(F33>=0.7,"ALERTA","OK")) -> ESTOURADO | Q35: =SUM(Q4:Q33) -> 0
A37: RESUMO AUTOMÁTICO DE HORAS
A39: Total Dias Previsto | D39: =SUM(E4:E33) -> 0 | F39: =D39/24 -> 0 | G39: dias
A40: Total dias Imprevisto | D40: =SUM(F4:F33) -> 3 | F40: =D40/24 -> 0.125 | G40: dias
A41: Margem Imprevista | D41: =G35 -> 3 | F41: =D41/24 -> 0.125 | G41: dias
B52: ver se coloca os equipamentos da DH tambem para fazer contagem de dias parados por problemas de manutenção separado?

Sheet DASHBOARD PERFURAÇÃO
A1: DASHBOARD - CONTROLE DE PERFURAÇÃO

Sheet DASHBOARD
A1: DASHBOARD - CONTROLE DE HORAS PARADAS
A5: Horas Totais | B5: =Abril!C40+'Maio '!C42+JUNHO!D42+JULHO!D42 -> 17.13125 | D5: Categoria | E5: Horas
A6: Horas Trabalhadas | B6: =SUM(Abril!C41+'Maio '!C43+JUNHO!D43+JULHO!D43) -> 16.058333 | D6: DH-GEL ENGENHARIA | E6: =B8 -> 0.069444444
A7: Horas Paradas | B7: =SUM(Abril!C42+'Maio '!C44+JUNHO!D44+JULHO!D44) -> 1.0729167 | D7: SANEPAR | E7: =B9 -> 0
A8: Parada DH-GEL ENGENHARIA | B8: =SUM(Abril!C43+'Maio '!C45+JUNHO!D45+JULHO!D45) -> 0.069444444 | D8: Chuva | E8: =B10 -> 0.52777778
A9: Parada SANEPAR | B9: =SUM(Abril!C44+'Maio '!C46+JUNHO!D46+JULHO!D46) -> 0 | D9: Mecânica | E9: =B11 -> 0.16666667
A10: Parada Chuva | B10: =SUM(Abril!C45+'Maio '!C47+JUNHO!D47+JULHO!D47) -> 0.52777778
A11: Parada Mecânica | B11: =SUM(Abril!C46+'Maio '!C48+JUNHO!D48+JULHO!D48) -> 0.16666667
D12: Mensal | E12: Trabalhada
D13: Abril | E13: =Abril!C41 -> 3.28125
D14: Maio | E14: =SUM('Maio '!C43) -> 12.777083
A15: Tipo | B15: Horas | D15: Junho | E15: =JUNHO!D43 -> 0
A16: DH-GEL ENGENHARIA | B16: =B8 -> 0.069444444
A17: SANEPAR | B17: =B9 -> 0
A18: Chuva | B18: =B10 -> 0.52777778
A19: Parada Mecânica | B19: =B11 -> 0.16666667

Sheet DISTRIBUIÇÃO DE HORAS PARADAS
A1: HORAS - TOTAL DE PARALIZAÇÃO DO PROJETO
A4: MRV - Reserva Romana | B4: Horas | C4: Dias | E4: DH-GEL ENGENHARIA | F4: Horas | G4: Dias | I4: Horas | J4: Dias
A5: Administrativo | B5: =SUM(#REF!+Abril!I32+'Maio '!I7+'Maio '!I8+'Maio '!I9+'Maio '!I10+'Maio '!I26) -> #REF! | C5: =B5/10 -> #REF! | E5: Falta de Equipe/Administrativo | F5: =DASHBOARD!B16 -> 0.069444444 | G5: =F5/24 -> 0.0028935185 | H5: Manutenção | I5: =EQUIPAMENTOS!B67 -> 0 | J5: =I5/24 -> 0
A6: Fornecimento de Água | B6: =SUM('Maio '!I16) -> 0 | C6: =B6/10 -> 0 | E6: Manutenção de Equipamentos | F6: =DASHBOARD!B11 -> 0.16666667 | G6: =F6/24 -> 0.0069444444
E7: Chuva | F7: =DASHBOARD!B10 -> 0.52777778 | G7: =F7/24 -> 0.021990741

Sheet DASHBOARD MENSAL
A1: PORCENTAGEM MENSAL DE PRODUTIVIDADE DO PROJETO
A4: Mês | B4: Horas Trabalhadas | C4: Horas Paradas
A5: Abril | B5: =SUM(Abril!C41) -> 3.28125 | C5: =SUM(Abril!C42) -> 0.16666667
A6: Maio | B6: =SUM('Maio '!C43) -> 12.777083 | C6: =SUM('Maio '!C44) -> 0.90625

Sheet DASHBOARD GERAL DE EXECUÇÃO
A1: DIAS - TOTAL GERAL DO PROJETO
A4: Mês | B4: Inicio | C4: Previsto | D4: Termino | E4: Total Dias Realizados | F4: Total Dias Previsto | G4: Total Dias Restantes | H4: Porcentagem de Atraso
A5: SANEPAR | B5: 46104 | C5: 46284 | D5: 46204 | E5: =SUM(D5-B5) -> 100 | F5: =SUM(C5-B5) -> 180 | G5: =SUM(F5-E5) -> 80 | H5: =(G5/F5) -> 0.44444444
B6: 46132 | C6: 46232 | D6: =C6-B6 -> 100
G8: Dias Efetivos de Operação | H8: Horas | J8: Dias de Operações
G9: Horas Totais | H9: =SUM(#REF!+#REF!+Abril!C40+'Maio '!C42) -> #REF! | J9: =H9 -> #REF!
G10: Horas Trabalhadas | H10: =SUM(#REF!+#REF!+Abril!C41+'Maio '!C43) -> #REF! | J10: =H10 -> #REF!
G11: Horas Paradas | H11: =SUM(#REF!+#REF!+Abril!C42+'Maio '!C44) -> #REF! | J11: =H11 -> #REF!
G12: Parada DH-GEL ENGENHARIA | H12: =SUM(#REF!+#REF!+Abril!C43+'Maio '!C45) -> #REF! | J12: =H12 -> #REF!
G13: Parada SANEPAR | H13: =SUM(#REF!+#REF!+Abril!C44+'Maio '!C46) -> #REF! | J13: =H13 -> #REF!
G14: Parada Chuva | H14: =SUM(#REF!+#REF!+Abril!C45+'Maio '!C47) -> #REF! | J14: =H14 -> #REF!
G15: Parada Mecânica | H15: =SUM(#REF!+#REF!+Abril!C46+'Maio '!C48) -> #REF! | J15: =H15 -> #REF!
G18: Horas Paradas DH-GEL ENGENHARIA
G19: Administrativo/ Falta de Equipe | H19: =SUM(#REF!+#REF!+Abril!H36+'Maio '!H37) -> #REF!
G20: Mecânica / Eletricista | H20: =SUM(#REF!+#REF!+Abril!M36+'Maio '!N37) -> #REF!
